Workbook
Name SegmentaciónDeDatos_Vendedor: #N/A

Sheet Datos
H2: Inversiones Agropecuarias Lom SAS | M2: 46036 | N2: 0.69438657
H4: 901399676-1
H5: AV CIUDAD DE CALI15A -91 LOCAL A19 - A20
H7: Cartera Por Edades | N7: R550103
A10: 4G FOOD SAS | J10: Telefono: | K10: 3112550306 | L10: Días Vencidos
A12: Tipo | B12: Numero | C12: Ven | D12: Factura | E12: Vencimiento | G12: Valor_Total | H12: Saldo | I12: Sin_Vencer | J12: 1_a_8 | K12: 9_a_15 | L12: 16_a_22 | M12: 23_a_30 | N12: >30
A13: 751 | B13: 18568 | C13: 8 | D13: 46007.561 | E13: 46022.561 | F13: 14 | G13: 1128900 | H13: 1128900 | I13: 0 | J13: 0 | K13: 1128900 | L13: 0 | M13: 0 | N13: 0
A14: 751 | B14: 18708 | C14: 8 | D14: 46010.552 | E14: 46025.552 | F14: 11 | G14: 524700 | H14: 524700 | I14: 0 | J14: 0 | K14: 524700 | L14: 0 | M14: 0 | N14: 0
A15: 751 | B15: 18988 | C15: 8 | D15: 46020.562 | E15: 46035.561 | F15: 1 | G15: 816200 | H15: 816200 | I15: 0 | J15: 816200 | K15: 0 | L15: 0 | M15: 0 | N15: 0
B16: Total: | D16: =SUBTOTAL(4,F13:F15) -> 14
G17: =SUBTOTAL(9,H13:H15) -> 2469800 | H17: =SUBTOTAL(9,I13:I15) -> 0 | I17: =SUBTOTAL(9,J13:J15) -> 816200 | K17: =SUBTOTAL(9,K13:K15) -> 1653600 | L17: =SUBTOTAL(9,L13:L15) -> 0 | M17: =SUBTOTAL(9,M13:M15) -> 0 | N17: =SUBTOTAL(9,N13:N15) -> 0
A18: A TEAM CG SAS | J18: Telefono: | K18: 6017044813 | L18: Días Vencidos
A20: Tipo | B20: Numero | C20: Ven | D20: Factura | E20: Vencimiento | G20: Valor_Total | H20: Saldo | I20: Sin_Vencer | J20: 1_a_8 | K20: 9_a_15 | L20: 16_a_22 | M20: 23_a_30 | N20: >30
A21: 151 | B21: 22568 | C21: 3 | D21: 45982.405 | E21: 46012.404 | F21: 24 | G21: 461500 | H21: 461500 | I21: 0 | J21: 0 | K21: 0 | L21: 0 | M21: 461500 | N21: 0
A22: 151 | B22: 22700 | C22: 3 | D22: 45987.306 | E22: 46017.305 | F22: 19 | G22: 248400 | H22: 248400 | I22: 0 | J22: 0 | K22: 0 | L22: 248400 | M22: 0 | N22: 0
A23: 151 | B23: 22763 | C23: 3 | D23: 45989.345 | E23: 46019.345 | F23: 17 | G23: 158900 | H23: 158900 | I23: 0 | J23: 0 | K23: 0 | L23: 158900 | M23: 0 | N23: 0
A24: 151 | B24: 22783 | C24: 3 | D24: 45990.292 | E24: 46020.29 | F24: 16 | G24: 800600 | H24: 800600 | I24: 0 | J24: 0 | K24: 0 | L24: 800600 | M24: 0 | N24: 0
A25: 151 | B25: 22942 | C25: 3 | D25: 45995.275 | E25: 46025.275 | F25: 11 | G25: 260000 | H25: 260000 | I25: 0 | J25: 0 | K25: 260000 | L25: 0 | M25: 0 | N25: 0
A26: 151 | B26: 23011 | C26: 3 | D26: 45997.255 | E26: 46027.255 | F26: 9 | G26: 464600 | H26: 464600 | I26: 0 | J26: 0 | K26: 464600 | L26: 0 | M26: 0 | N26: 0
A27: 151 | B27: 23072 | C27: 3 | D27: 46000.337 | E27: 46030.337 | F27: 6 | G27: 304500 | H27: 304500 | I27: 0 | J27: 304500 | K27: 0 | L27: 0 | M27: 0 | N27: 0
A28: 151 | B28: 23474 | C28: 3 | D28: 46011.331 | E28: 46041.33 | F28: -5 | G28: 154900 | H28: 154900 | I28: 154900 | J28: 0 | K28: 0 | L28: 0 | M28: 0 | N28: 0
A29: 151 | B29: 23695 | C29: 3 | D29: 46020.184 | E29: 46050.184 | F29: -14 | G29: 219700 | H29: 219700 | I29: 219700 | J29: 0 | K29: 0 | L29: 0 | M29: 0 | N29: 0
B30: Total: | D30: =SUBTOTAL(4,F21:F29) -> 24
G31: =SUBTOTAL(9,H21:H29) -> 3073100 | H31: =SUBTOTAL(9,I21:I29) -> 374600 | I31: =SUBTOTAL(9,J21:J29) -> 304500 | K31: =SUBTOTAL(9,K21:K29) -> 724600 | L31: =SUBTOTAL(9,L21:L29) -> 1207900 | M31: =SUBTOTAL(9,M21:M29) -> 461500 | N31: =SUBTOTAL(9,N21:N29) -> 0
A32: ABEL Y SOFIA SAS | J32: Telefono: | K32: 7044813 | L32: Días Vencidos
A34: Tipo | B34: Numero | C34: Ven | D34: Factura | E34: Vencimiento | G34: Valor_Total | H34: Saldo | I34: Sin_Vencer | J34: 1_a_8 | K34: 9_a_15 | L34: 16_a_22 | M34: 23_a_30 | N34: >30
A35: 151 | B35: 20290 | C35: 0 | D35: 45873.302 | E35: 45903.301 | F35: 133 | G35: 114299.99 | H35: 84299.99 | I35: 0 | J35: 0 | K35: 0 | L35: 0 | M35: 0 | N35: 84299.99
A36: 151 | B36: 21715 | C36: 0 | D36: 45945.312 | E36: 45975.312 | F36: 61 | G36: 393300 | H36: 371495 | I36: 0 | J36: 0 | K36: 0 | L36: 0 | M36: 0 | N36: 371495
A37: 151 | B37: 22119 | C37: 0 | D37: 45962.307 | E37: 45992.307 | F37: 44 | G37: 1772250 | H37: 1772250 | I37: 0 | J37: 0 | K37: 0 | L37: 0 | M37: 0 | N37: 1772250
A38: 151 | B38: 22121 | C38: 0 | D38: 45962.31 | E38: 45992.31 | F38: 44 | G38: 487600 | H38: 487600 | I38: 0 | J38: 0 | K38: 0 | L38: 0 | M38: 0 | N38: 487600
A39: 151 | B39: 22124 | C39: 0 | D39: 45962.317 | E39: 45992.317 | F39: 44 | G39: 150800 | H39: 150800 | I39: 0 | J39: 0 | K39: 0 | L39: 0 | M39: 0 | N39: 150800
A40: 151 | B40: 22125 | C40: 0 | D40: 45962.318 | E40: 45992.317 | F40: 44 | G40: 343300 | H40: 343300 | I40: 0 | J40: 0 | K40: 0 | L40: 0 | M40: 0 | N40: 343300
A41: 151 | B41: 22131 | C41: 0 | D41: 45962.377 | E41: 45992.377 | F41: 44 | G41: 1200000 | H41: 1200000 | I41: 0 | J41: 0 | K41: 0 | L41: 0 | M41: 0 | N41: 1200000
A42: 151 | B42: 22151 | C42: 0 | D42: 45965.291 | E42: 45995.287 | F42: 41 | G42: 195999.97 | H42: 195999.97 | I42: 0 | J42: 0 | K42: 0 | L42: 0 | M42: 0 | N42: 195999.97
A43: 151 | B43: 22152 | C43: 0 | D43: 45965.293 | E43: 45995.292 | F43: 41 | G43: 82899.99 | H43: 82899.99 | I43: 0 | J43: 0 | K43: 0 | L43: 0 | M43: 0 | N43: 82899.99
A44: 151 | B44: 22173 | C44: 0 | D44: 45966.285 | E44: 45996.284 | F44: 40 | G44: 178899.99 | H44: 178899.99 | I44: 0 | J44: 0 | K44: 0 | L44: 0 | M44: 0 | N44: 178899.99
A45: 151 | B45: 22174 | C45: 0 | D45: 45966.287 | E45: 45996.286 | F45: 40 | G45: 415850 | H45: 415850 | I45: 0 | J45: 0 | K45: 0 | L45: 0 | M45: 0 | N45: 415850
A46: 151 | B46: 22176 | C46: 0 | D46: 45966.288 | E46: 45996.288 | F46: 40 | G46: 342200 | H46: 342200 | I46: 0 | J46: 0 | K46: 0 | L46: 0 | M46: 0 | N46: 342200
... A206: 151 | B206: 23737 | C206: 0 | D206: 46021.345 | E206: 46051.344 | F206: -15 | G206: 1816900 | H206: 1816900 | I206: 1816900 | J206: 0 | K206: 0 | L206: 0 | M206: 0 | N206: 0
B207: Total: | D207: =SUBTOTAL(4,F35:F206) -> 133
...

Sheet Datos (3)
A11: Forma de Pago | B11: Fecha | C11: Tipo | D11: Documento | E11: Numero | F11: Valor | G11: Asociado | H11: Usuario
A12: COLPATRIA | B12: 45995 | C12: 707 | D12: Recibos de Caja Galan | E12: 7743 | F12: 73803088 | G12: 0 | H12: OFICINA
A13: COLPATRIA | B13: 45995 | C13: 707 | D13: Recibos de Caja Galan | E13: 7750 | F13: 2908500 | G13: 0 | H13: OFICINA
A14: Datafono | B14: 45996.274 | C14: 155 | D14: Venta Electronica POS LOM | E14: 56985 | F14: 339763 | G14: 0 | H14: CAJAL2
A15: Datafono | B15: 45992.324 | C15: 155 | D15: Venta Electronica POS LOM | E15: 56765 | F15: 115864 | G15: 0 | H15: caja1
A16: Datafono | B16: 45992.328 | C16: 155 | D16: Venta Electronica POS LOM | E16: 56766 | F16: 64760 | G16: 0 | H16: caja1
A17: Datafono | B17: 45992.441 | C17: 155 | D17: Venta Electronica POS LOM | E17: 56777 | F17: 20160 | G17: 0 | H17: CAJAL3
A18: Datafono | B18: 45992.446 | C18: 155 | D18: Venta Electronica POS LOM | E18: 56778 | F18: 65376 | G18: 0 | H18: CAJAL3
A19: Datafono | B19: 45992.38 | C19: 155 | D19: Venta Electronica POS LOM | E19: 56771 | F19: 42580 | G19: 0 | H19: CAJAL3
A20: Datafono | B20: 45992.387 | C20: 155 | D20: Venta Electronica POS LOM | E20: 56772 | F20: 105948 | G20: 0 | H20: CAJAL3
A21: Datafono | B21: 45993.2 | C21: 155 | D21: Venta Electronica POS LOM | E21: 56785 | F21: 302698 | G21: 0 | H21: CAJAL2
A22: Datafono | B22: 45993.223 | C22: 155 | D22: Venta Electronica POS LOM | E22: 56789 | F22: 112892 | G22: 0 | H22: CAJAL2
A23: Datafono | B23: 45993.269 | C23: 155 | D23: Venta Electronica POS LOM | E23: 56797 | F23: 186280 | G23: 0 | H23: CAJAL2
... A1088: Transferencia Bancolombia | B1088: 45995.61 | C1088: 755 | D1088: Venta Electronica POS M.GALAN | E1088: 75969 | F1088: 30005 | G1088: 0 | H1088: CAJAG4

Sheet Datos (2)
I1: Inversiones Agropecuarias Lom SAS
I4: 901399676-1
I5: AV CIUDAD DE CALI15A -91 LOCAL A19 - A20
I7: Cartera Por Edades
A9: Cliente | B9: Tipo | C9: Numero | D9: Ven | E9: Factura | F9: Vencimiento | H9: Valor_Total | I9: Saldo | J9: Sin_Vencer | K9: 1_a_8 | L9: 9_a_15 | M9: 16_a_22 | N9: 23_a_30 | O9: >30
A10: 4G FOOD SAS | B10: 751 | C10: 18568 | D10: 8 | E10: 46007 | F10: 46022 | G10: -7 | H10: 1128900 | I10: 1128900 | J10: 1128900 | K10: 0 | L10: 0 | M10: 0 | N10: 0 | O10: 0
A11: 4G FOOD SAS | B11: 751 | C11: 18708 | D11: 8 | E11: 46010 | F11: 46025 | G11: -10 | H11: 524700 | I11: 524700 | J11: 524700 | K11: 0 | L11: 0 | M11: 0 | N11: 0 | O11: 0
A12: A MANO SAS | B12: 751 | C12: 18742 | D12: 4 | E12: 46011 | F12: 46019 | G12: -4 | H12: 354200 | I12: 354200 | J12: 354200 | K12: 0 | L12: 0 | M12: 0 | N12: 0 | O12: 0
A13: A TEAM CG SAS | B13: 151 | C13: 22568 | D13: 3 | E13: 45982 | F13: 46012 | G13: 3 | H13: 461500 | I13: 461500 | J13: 0 | K13: 461500 | L13: 0 | M13: 0 | N13: 0 | O13: 0
A14: A TEAM CG SAS | B14: 151 | C14: 22700 | D14: 3 | E14: 45987 | F14: 46017 | G14: -2 | H14: 248400 | I14: 248400 | J14: 248400 | K14: 0 | L14: 0 | M14: 0 | N14: 0 | O14: 0
A15: A TEAM CG SAS | B15: 151 | C15: 22763 | D15: 3 | E15: 45989 | F15: 46019 | G15: -4 | H15: 158900 | I15: 158900 | J15: 158900 | K15: 0 | L15: 0 | M15: 0 | N15: 0 | O15: 0
A16: A TEAM CG SAS | B16: 151 | C16: 22783 | D16: 3 | E16: 45990 | F16: 46020 | G16: -5 | H16: 800600 | I16: 800600 | J16: 800600 | K16: 0 | L16: 0 | M16: 0 | N16: 0 | O16: 0
A17: A TEAM CG SAS | B17: 151 | C17: 22942 | D17: 3 | E17: 45995 | F17: 46025 | G17: -10 | H17: 260000 | I17: 260000 | J17: 260000 | K17: 0 | L17: 0 | M17: 0 | N17: 0 | O17: 0
A18: A TEAM CG SAS | B18: 151 | C18: 23011 | D18: 3 | E18: 45997 | F18: 46027 | G18: -12 | H18: 464600 | I18: 464600 | J18: 464600 | K18: 0 | L18: 0 | M18: 0 | N18: 0 | O18: 0
A19: A TEAM CG SAS | B19: 151 | C19: 23072 | D19: 3 | E19: 46000 | F19: 46030 | G19: -15 | H19: 304500 | I19: 304500 | J19: 304500 | K19: 0 | L19: 0 | M19: 0 | N19: 0 | O19: 0
A20: A TEAM CG SAS | B20: 151 | C20: 23474 | D20: 3 | E20: 46011 | F20: 46041 | G20: -26 | H20: 154900 | I20: 154900 | J20: 154900 | K20: 0 | L20: 0 | M20: 0 | N20: 0 | O20: 0
A21: ABDONINO POLOCHE BOSOS | B21: 751 | C21: 18767 | D21: 7 | E21: 46011 | F21: 46012 | G21: 3 | H21: 49990 | I21: 49990 | J21: 0 | K21: 49990 | L21: 0 | M21: 0 | N21: 0 | O21: 0
... A1568: YUDY CATERINY MORALES ROJAS | B1568: 151 | C1568: 23575 | D1568: 13 | E1568: 46015 | F1568: 46016 | G1568: -1 | H1568: 130500 | I1568: 130500 | J1568: 130500 | K1568: 0 | L1568: 0 | M1568: 0 | N1568: 0 | O1568: 0

Sheet Cartera por edades
A1: Cartera Por Edades | E1: Fecha actual | F1: =+TODAY() -> 46044
E2: Fecha cartera | F2: 46022
A5: =SI([@Tipo]>0;B13;"") | H5: =700000000/320 -> 2187500 | I5: 434332
A6: Nombre tercero | B6: Tipo | C6: Numero FAC | D6: V | E6: Emision | F6: Vencimiento | G6: Dias | H6: Valor_Total | I6: Saldo | J6: Sin_Vencer | K6: 1_a_8 | L6: 9_a_15 | M6: 16_a_22 | N6: 23_a_30 | O6: >30 | P6: Total vencido | Q6: De 9 a 30 | R6: Mas de 9 | S6: Dias >9 | T6: Mas de 100 | U6: Dias >100 | V6: Plazo cliente | W6: Local | X6: Vendedor | Y6: Revisar
A7: 4G FOOD SAS | B7: 751 | C7: 18568 | D7: 8 | E7: 46007.561 | F7: 46022.561 | G7: 14 | H7: 1128900 | I7: 1128900 | J7: 0 | K7: 0 | L7: 1128900 | M7: 0 | N7: 0 | O7: 0 | P7: =SUM(Cartera[[#This Row],[1_a_8]:[>30]]) -> 1128900 | Q7: =+Cartera[[#This Row],[9_a_15]]+Cartera[[#This Row],[16_a_22]]+Cartera[[#This Row],[23_a_30]] -> 1128900 | R7: =IF(Cartera[[#This Row],[Dias]]>8,Cartera[[#This Row],[Total vencido]],0) -> 1128900 | S7: =IF(Cartera[[#This Row],[Mas de 9]]>0,Cartera[[#This Row],[Dias]],0) -> 14 | T7: =IF(Cartera[[#This Row],[Dias]]>99,Cartera[[#This Row],[Total vencido]],0) -> 0 | U7: =IF(Cartera[[#This Row],[Mas de 100]]>0,Cartera[[#This Row],[Dias]],0) -> 0 | V7: =Cartera[[#This Row],[Vencimiento]]-Cartera[[#This Row],[Emision]] -> 14.999861 | W7: =+IF(Cartera[[#This Row],[Tipo]]=151,"Lom",IF(Cartera[[#This Row],[Tipo]]=153,"Lom",IF(Cartera[[#This Row],[Tipo]]=155,"Lom",IF(Cartera[[#This Row],[Tipo]]=200,"Lom",IF(Cartera[[#This Row],[Tipo]]=224,"Lom",IF(Cartera[[#This Row],[Tipo]]=251,"Lom",IF(Cartera[[#This Row],[Tipo]]=651,"Magra",IF(Cartera[[#This Row],[Tipo]]=655,"Magra",IF(Cartera[[#This Row],[Tipo]]=601,"Magra",IF(Cartera[[#This Row],[Tipo]]=751,"Galan",IF(Cartera[[#This Row],[Tipo]]=757,"Galan",IF(Cartera[[#This Row],[Tipo]]=701,"Galan",IF(Cartera[[#This Row],[Tipo]]=755,"Galan",IF(Cartera[[#This Row],[Tipo]]="CO","Conciliacion Cartera","")))))))))))))) | X7: =_xlfn.XLOOKUP(Cartera[[#This Row],[Nombre tercero]],Vendedor[Nombre],Vendedor[Vendedor],"",0,-1) -> WILLIAM DARIO PADILLA
A8: =+A7 -> 4G FOOD SAS | B8: 751 | C8: 18708 | D8: 8 | E8: 46010.552 | F8: 46025.552 | G8: 11 | H8: 524700 | I8: 524700 | J8: 0 | K8: 0 | L8: 524700 | M8: 0 | N8: 0 | O8: 0 | P8: =SUM(Cartera[[#This Row],[1_a_8]:[>30]]) -> 524700 | Q8: =+Cartera[[#This Row],[9_a_15]]+Cartera[[#This Row],[16_a_22]]+Cartera[[#This Row],[23_a_30]] -> 524700 | R8: =IF(Cartera[[#This Row],[Dias]]>8,Cartera[[#This Row],[Total vencido]],0) -> 524700 | S8: =IF(Cartera[[#This Row],[Mas de 9]]>0,Cartera[[#This Row],[Dias]],0) -> 11 | T8: =IF(Cartera[[#This Row],[Dias]]>99,Cartera[[#This Row],[Total vencido]],0) -> 0 | U8: =IF(Cartera[[#This Row],[Mas de 100]]>0,Cartera[[#This Row],[Dias]],0) -> 0 | V8: =Cartera[[#This Row],[Vencimiento]]-Cartera[[#This Row],[Emision]] -> 14.999757 | W8: =+IF(Cartera[[#This Row],[Tipo]]=151,"Lom",IF(Cartera[[#This Row],[Tipo]]=153,"Lom",IF(Cartera[[#This Row],[Tipo]]=155,"Lom",IF(Cartera[[#This Row],[Tipo]]=200,"Lom",IF(Cartera[[#This Row],[Tipo]]=224,"Lom",IF(Cartera[[#This Row],[Tipo]]=251,"Lom",IF(Cartera[[#This Row],[Tipo]]=651,"Magra",IF(Cartera[[#This Row],[Tipo]]=655,"Magra",IF(Cartera[[#This Row],[Tipo]]=601,"Magra",IF(Cartera[[#This Row],[Tipo]]=751,"Galan",IF(Cartera[[#This Row],[Tipo]]=757,"Galan",IF(Cartera[[#This Row],[Tipo]]=701,"Galan",IF(Cartera[[#This Row],[Tipo]]=755,"Galan",IF(Cartera[[#This Row],[Tipo]]="CO","Conciliacion Cartera","")))))))))))))) | X8: =_xlfn.XLOOKUP(Cartera[[#This Row],[Nombre tercero]],Vendedor[Nombre],Vendedor[Vendedor],"",0,-1) -> WILLIAM DARIO PADILLA
A9: =+A8 -> 4G FOOD SAS | B9: 751 | C9: 18988 | D9: 8 | E9: 46020.562 | F9: 46035.561 | G9: 1 | H9: 816200 | I9: 816200 | J9: 0 | K9: 816200 | L9: 0 | M9: 0 | N9: 0 | O9: 0 | P9: =SUM(Cartera[[#This Row],[1_a_8]:[>30]]) -> 816200 | Q9: =+Cartera[[#This Row],[9_a_15]]+Cartera[[#This Row],[16_a_22]]+Cartera[[#This Row],[23_a_30]] -> 0 | R9: =IF(Cartera[[#This Row],[Dias]]>8,Cartera[[#This Row],[Total vencido]],0) -> 0 | S9: =IF(Cartera[[#This Row],[Mas de 9]]>0,Cartera[[#This Row],[Dias]],0) -> 0 | T9: =IF(Cartera[[#This Row],[Dias]]>99,Cartera[[#This Row],[Total vencido]],0) -> 0 | U9: =IF(Cartera[[#This Row],[Mas de 100]]>0,Cartera[[#This Row],[Dias]],0) -> 0 | V9: =Cartera[[#This Row],[Vencimiento]]-Cartera[[#This Row],[Emision]] -> 14.999005 | W9: =+IF(Cartera[[#This Row],[Tipo]]=151,"Lom",IF(Cartera[[#This Row],[Tipo]]=153,"Lom",IF(Cartera[[#This Row],[Tipo]]=155,"Lom",IF(Cartera[[#This Row],[Tipo]]=200,"Lom",IF(Cartera[[#This Row],[Tipo]]=224,"Lom",IF(Cartera[[#This Row],[Tipo]]=251,"Lom",IF(Cartera[[#This Row],[Tipo]]=651,"Magra",IF(Cartera[[#This Row],[Tipo]]=655,"Magra",IF(Cartera[[#This Row],[Tipo]]=601,"Magra",IF(Cartera[[#This Row],[Tipo]]=751,"Galan",IF(Cartera[[#This Row],[Tipo]]=757,"Galan",IF(Cartera[[#This Row],[Tipo]]=701,"Galan",IF(Cartera[[#This Row],[Tipo]]=755,"Galan",IF(Cartera[[#This Row],[Tipo]]="CO","Conciliacion Cartera","")))))))))))))) | X9: =_xlfn.XLOOKUP(Cartera[[#This Row],[Nombre tercero]],Vendedor[Nombre],Vendedor[Vendedor],"",0,-1) -> WILLIAM DARIO PADILLA
A10: A TEAM CG SAS | B10: 151 | C10: 22568 | D10: 3 | E10: 45982.405 | F10: 46012.404 | G10: 24 | H10: 461500 | I10: 461500 | J10: 0 | K10: 0 | L10: 0 | M10: 0 | N10: 461500 | O10: 0 | P10: =SUM(Cartera[[#This Row],[1_a_8]:[>30]]) -> 461500 | Q10: =+Cartera[[#This Row],[9_a_15]]+Cartera[[#This Row],[16_a_22]]+Cartera[[#This Row],[23_a_30]] -> 461500 | R10: =IF(Cartera[[#This Row],[Dias]]>8,Cartera[[#This Row],[Total vencido]],0) -> 461500 | S10: =IF(Cartera[[#This Row],[Mas de 9]]>0,Cartera[[#This Row],[Dias]],0) -> 24 | T10: =IF(Cartera[[#This Row],[Dias]]>99,Cartera[[#This Row],[Total vencido]],0) -> 0 | U10: =IF(Cartera[[#This Row],[Mas de 100]]>0,Cartera[[#This Row],[Dias]],0) -> 0 | V10: =Cartera[[#This Row],[Vencimiento]]-Cartera[[#This Row],[Emision]] -> 29.998819 | W10: =+IF(Cartera[[#This Row],[Tipo]]=151,"Lom",IF(Cartera[[#This Row],[Tipo]]=153,"Lom",IF(Cartera[[#This Row],[Tipo]]=155,"Lom",IF(Cartera[[#This Row],[Tipo]]=200,"Lom",IF(Cartera[[#This Row],[Tipo]]=224,"Lom",IF(Cartera[[#This Row],[Tipo]]=251,"Lom",IF(Cartera[[#This Row],[Tipo]]=651,"Magra",IF(Cartera[[#This Row],[Tipo]]=655,"Magra",IF(Cartera[[#This Row],[Tipo]]=601,"Magra",IF(Cartera[[#This Row],[Tipo]]=751,"Galan",IF(Cartera[[#This Row],[Tipo]]=757,"Galan",IF(Cartera[[#This Row],[Tipo]]=701,"Galan",IF(Cartera[[#This Row],[Tipo]]=755,"Galan",IF(Cartera[[#This Row],[Tipo]]="CO","Conciliacion Cartera","")))))))))))))) | X10: =_xlfn.XLOOKUP(Cartera[[#This Row],[Nombre tercero]],Vendedor[Nombre],Vendedor[Vendedor],"",0,-1) -> ANGELA SILVESTRE | Y10: BONO
A11: =+A10 -> A TEAM CG SAS | B11: 151 | C11: 22700 | D11: 3 | E11: 45987.306 | F11: 46017.305 | G11: 19 | H11: 248400 | I11: 248400 | J11: 0 | K11: 0 | L11: 0 | M11: 248400 | N11: 0 | O11: 0 | P11: =SUM(Cartera[[#This Row],[1_a_8]:[>30]]) -> 248400 | Q11: =+Cartera[[#This Row],[9_a_15]]+Cartera[[#This Row],[16_a_22]]+Cartera[[#This Row],[23_a_30]] -> 248400 | R11: =IF(Cartera[[#This Row],[Dias]]>8,Cartera[[#This Row],[Total vencido]],0) -> 248400 | S11: =IF(Cartera[[#This Row],[Mas de 9]]>0,Cartera[[#This Row],[Dias]],0) -> 19 | T11: =IF(Cartera[[#This Row],[Dias]]>99,Cartera[[#This Row],[Total vencido]],0) -> 0 | U11: =IF(Cartera[[#This Row],[Mas de 100]]>0,Cartera[[#This Row],[Dias]],0) -> 0 | V11: =Cartera[[#This Row],[Vencimiento]]-Cartera[[#This Row],[Emision]] -> 29.99963 | W11: =+IF(Cartera[[#This Row],[Tipo]]=151,"Lom",IF(Cartera[[#This Row],[Tipo]]=153,"Lom",IF(Cartera[[#This Row],[Tipo]]=155,"Lom",IF(Cartera[[#This Row],[Tipo]]=200,"Lom",IF(Cartera[[#This Row],[Tipo]]=224,"Lom",IF(Cartera[[#This Row],[Tipo]]=251,"Lom",IF(Cartera[[#This Row],[Tipo]]=651,"Magra",IF(Cartera[[#This Row],[Tipo]]=655,"Magra",IF(Cartera[[#This Row],[Tipo]]=601,"Magra",IF(Cartera[[#This Row],[Tipo]]=751,"Galan",IF(Cartera[[#This Row],[Tipo]]=757,"Galan",IF(Cartera[[#This Row],[Tipo]]=701,"Galan",IF(Cartera[[#This Row],[Tipo]]=755,"Galan",IF(Cartera[[#This Row],[Tipo]]="CO","Conciliacion Cartera","")))))))))))))) | X11: =_xlfn.XLOOKUP(Cartera[[#This Row],[Nombre tercero]],Vendedor[Nombre],Vendedor[Vendedor],"",0,-1) -> ANGELA SILVESTRE
A12: =+A11 -> A TEAM CG SAS | B12: 151 | C12: 22763 | D12: 3 | E12: 45989.345 | F12: 46019.345 | G12: 17 | H12: 158900 | I12: 158900 | J12: 0 | K12: 0 | L12: 0 | M12: 158900 | N12: 0 | O12: 0 | P12: =SUM(Cartera[[#This Row],[1_a_8]:[>30]]) -> 158900 | Q12: =+Cartera[[#This Row],[9_a_15]]+Cartera[[#This Row],[16_a_22]]+Cartera[[#This Row],[23_a_30]] -> 158900 | R12: =IF(Cartera[[#This Row],[Dias]]>8,Cartera[[#This Row],[Total vencido]],0) -> 158900 | S12: =IF(Cartera[[#This Row],[Mas de 9]]>0,Cartera[[#This Row],[Dias]],0) -> 17 | T12: =IF(Cartera[[#This Row],[Dias]]>99,Cartera[[#This Row],[Total vencido]],0) -> 0 | U12: =IF(Cartera[[#This Row],[Mas de 100]]>0,Cartera[[#This Row],[Dias]],0) -> 0 | V12: =Cartera[[#This Row],[Vencimiento]]-Cartera[[#This Row],[Emision]] -> 29.99985 | W12: =+IF(Cartera[[#This Row],[Tipo]]=151,"Lom",IF(Cartera[[#This Row],[Tipo]]=153,"Lom",IF(Cartera[[#This Row],[Tipo]]=155,"Lom",IF(Cartera[[#This Row],[Tipo]]=200,"Lom",IF(Cartera[[#This Row],[Tipo]]=224,"Lom",IF(Cartera[[#This Row],[Tipo]]=251,"Lom",IF(Cartera[[#This Row],[Tipo]]=651,"Magra",IF(Cartera[[#This Row],[Tipo]]=655,"Magra",IF(Cartera[[#This Row],[Tipo]]=601,"Magra",IF(Cartera[[#This Row],[Tipo]]=751,"Galan",IF(Cartera[[#This Row],[Tipo]]=757,"Galan",IF(Cartera[[#This Row],[Tipo]]=701,"Galan",IF(Cartera[[#This Row],[Tipo]]=755,"Galan",IF(Cartera[[#This Row],[Tipo]]="CO","Conciliacion Cartera","")))))))))))))) | X12: =_xlfn.XLOOKUP(Cartera[[#This Row],[Nombre tercero]],Vendedor[Nombre],Vendedor[Vendedor],"",0,-1) -> ANGELA SILVESTRE
A13: =+A12 -> A TEAM CG SAS | B13: 151 | C13: 22783 | D13: 3 | E13: 45990.292 | F13: 46020.29 | G13: 16 | H13: 800600 | I13: 800600 | J13: 0 | K13: 0 | L13: 0 | M13: 800600 | N13: 0 | O13: 0 | P13: =SUM(Cartera[[#This Row],[1_a_8]:[>30]]) -> 800600 | Q13: =+Cartera[[#This Row],[9_a_15]]+Cartera[[#This Row],[16_a_22]]+Cartera[[#This Row],[23_a_30]] -> 800600 | R13: =IF(Cartera[[#This Row],[Dias]]>8,Cartera[[#This Row],[Total vencido]],0) -> 800600 | S13: =IF(Cartera[[#This Row],[Mas de 9]]>0,Cartera[[#This Row],[Dias]],0) -> 16 | T13: =IF(Cartera[[#This Row],[Dias]]>99,Cartera[[#This Row],[Total vencido]],0) -> 0 | U13: =IF(Cartera[[#This Row],[Mas de 100]]>0,Cartera[[#This Row],[Dias]],0) -> 0 | V13: =Cartera[[#This Row],[Vencimiento]]-Cartera[[#This Row],[Emision]] -> 29.99794 | W13: =+IF(Cartera[[#This Row],[Tipo]]=151,"Lom",IF(Cartera[[#This Row],[Tipo]]=153,"Lom",IF(Cartera[[#This Row],[Tipo]]=155,"Lom",IF(Cartera[[#This Row],[Tipo]]=200,"Lom",IF(Cartera[[#This Row],[Tipo]]=224,"Lom",IF(Cartera[[#This Row],[Tipo]]=251,"Lom",IF(Cartera[[#This Row],[Tipo]]=651,"Magra",IF(Cartera[[#This Row],[Tipo]]=655,"Magra",IF(Cartera[[#This Row],[Tipo]]=601,"Magra",IF(Cartera[[#This Row],[Tipo]]=751,"Galan",IF(Cartera[[#This Row],[Tipo]]=757,"Galan",IF(Cartera[[#This Row],[Tipo]]=701,"Galan",IF(Cartera[[#This Row],[Tipo]]=755,"Galan",IF(Cartera[[#This Row],[Tipo]]="CO","Conciliacion Cartera","")))))))))))))) | X13: =_xlfn.XLOOKUP(Cartera[[#This Row],[Nombre tercero]],Vendedor[Nombre],Vendedor[Vendedor],"",0,-1) -> ANGELA SILVESTRE
A14: =+A13 -> A TEAM CG SAS | B14: 151 | C14: 22942 | D14: 3 | E14: 45995.275 | F14: 46025.275 | G14: 11 | H14: 260000 | I14: 260000 | J14: 0 | K14: 0 | L14: 260000 | M14: 0 | N14: 0 | O14: 0 | P14: =SUM(Cartera[[#This Row],[1_a_8]:[>30]]) -> 260000 | Q14: =+Cartera[[#This Row],[9_a_15]]+Cartera[[#This Row],[16_a_22]]+Cartera[[#This Row],[23_a_30]] -> 260000 | R14: =IF(Cartera[[#This Row],[Dias]]>8,Cartera[[#This Row],[Total vencido]],0) -> 260000 | S14: =IF(Cartera[[#This Row],[Mas de 9]]>0,Cartera[[#This Row],[Dias]],0) -> 11 | T14: =IF(Cartera[[#This Row],[Dias]]>99,Cartera[[#This Row],[Total vencido]],0) -> 0 | U14: =IF(Cartera[[#This Row],[Mas de 100]]>0,Cartera[[#This Row],[Dias]],0) -> 0 | V14: =Cartera[[#This Row],[Vencimiento]]-Cartera[[#This Row],[Emision]] -> 29.999884 | W14: =+IF(Cartera[[#This Row],[Tipo]]=151,"Lom",IF(Cartera[[#This Row],[Tipo]]=153,"Lom",IF(Cartera[[#This Row],[Tipo]]=155,"Lom",IF(Cartera[[#This Row],[Tipo]]=200,"Lom",IF(Cartera[[#This Row],[Tipo]]=224,"Lom",IF(Cartera[[#This Row],[Tipo]]=251,"Lom",IF(Cartera[[#This Row],[Tipo]]=651,"Magra",IF(Cartera[[#This Row],[Tipo]]=655,"Magra",IF(Cartera[[#This Row],[Tipo]]=601,"Magra",IF(Cartera[[#This Row],[Tipo]]=751,"Galan",IF(Cartera[[#This Row],[Tipo]]=757,"Galan",IF(Cartera[[#This Row],[Tipo]]=701,"Galan",IF(Cartera[[#This Row],[Tipo]]=755,"Galan",IF(Cartera[[#This Row],[Tipo]]="CO","Conciliacion Cartera","")))))))))))))) | X14: =_xlfn.XLOOKUP(Cartera[[#This Row],[Nombre tercero]],Vendedor[Nombre],Vendedor[Vendedor],"",0,-1) -> ANGELA SILVESTRE
A15: =+A14 -> A TEAM CG SAS | B15: 151 | C15: 23011 | D15: 3 | E15: 45997.255 | F15: 46027.255 | G15: 9 | H15: 464600 | I15: 464600 | J15: 0 | K15: 0 | L15: 464600 | M15: 0 | N15: 0 | O15: 0 | P15: =SUM(Cartera[[#This Row],[1_a_8]:[>30]]) -> 464600 | Q15: =+Cartera[[#This Row],[9_a_15]]+Cartera[[#This Row],[16_a_22]]+Cartera[[#This Row],[23_a_30]] -> 464600 | R15: =IF(Cartera[[#This Row],[Dias]]>8,Cartera[[#This Row],[Total vencido]],0) -> 464600 | S15: =IF(Cartera[[#This Row],[Mas de 9]]>0,Cartera[[#This Row],[Dias]],0) -> 9 | T15: =IF(Cartera[[#This Row],[Dias]]>99,Cartera[[#This Row],[Total vencido]],0) -> 0 | U15: =IF(Cartera[[#This Row],[Mas de 100]]>0,Cartera[[#This Row],[Dias]],0) -> 0 | V15: =Cartera[[#This Row],[Vencimiento]]-Cartera[[#This Row],[Emision]] -> 29.999873 | W15: =+IF(Cartera[[#This Row],[Tipo]]=151,"Lom",IF(Cartera[[#This Row],[Tipo]]=153,"Lom",IF(Cartera[[#This Row],[Tipo]]=155,"Lom",IF(Cartera[[#This Row],[Tipo]]=200,"Lom",IF(Cartera[[#This Row],[Tipo]]=224,"Lom",IF(Cartera[[#This Row],[Tipo]]=251,"Lom",IF(Cartera[[#This Row],[Tipo]]=651,"Magra",IF(Cartera[[#This Row],[Tipo]]=655,"Magra",IF(Cartera[[#This Row],[Tipo]]=601,"Magra",IF(Cartera[[#This Row],[Tipo]]=751,"Galan",IF(Cartera[[#This Row],[Tipo]]=757,"Galan",IF(Cartera[[#This Row],[Tipo]]=701,"Galan",IF(Cartera[[#This Row],[Tipo]]=755,"Galan",IF(Cartera[[#This Row],[Tipo]]="CO","Conciliacion Cartera","")))))))))))))) | X15: =_xlfn.XLOOKUP(Cartera[[#This Row],[Nombre tercero]],Vendedor[Nombre],Vendedor[Vendedor],"",0,-1) -> ANGELA SILVESTRE
A16: =+A15 -> A TEAM CG SAS | B16: 151 | C16: 23072 | D16: 3 | E16: 46000.337 | F16: 46030.337 | G16: 6 | H16: 304500 | I16: 304500 | J16: 0 | K16: 304500 | L16: 0 | M16: 0 | N16: 0 | O16: 0 | P16: =SUM(Cartera[[#This Row],[1_a_8]:[>30]]) -> 304500 | Q16: =+Cartera[[#This Row],[9_a_15]]+Cartera[[#This Row],[16_a_22]]+Cartera[[#This Row],[23_a_30]] -> 0 | R16: =IF(Cartera[[#This Row],[Dias]]>8,Cartera[[#This Row],[Total vencido]],0) -> 0 | S16: =IF(Cartera[[#This Row],[Mas de 9]]>0,Cartera[[#This Row],[Dias]],0) -> 0 | T16: =IF(Cartera[[#This Row],[Dias]]>99,Cartera[[#This Row],[Total vencido]],0) -> 0 | U16: =IF(Cartera[[#This Row],[Mas de 100]]>0,Cartera[[#This Row],[Dias]],0) -> 0 | V16: =Cartera[[#This Row],[Vencimiento]]-Cartera[[#This Row],[Emision]] -> 29.999884 | W16: =+IF(Cartera[[#This Row],[Tipo]]=151,"Lom",IF(Cartera[[#This Row],[Tipo]]=153,"Lom",IF(Cartera[[#This Row],[Tipo]]=155,"Lom",IF(Cartera[[#This Row],[Tipo]]=200,"Lom",IF(Cartera[[#This Row],[Tipo]]=224,"Lom",IF(Cartera[[#This Row],[Tipo]]=251,"Lom",IF(Cartera[[#This Row],[Tipo]]=651,"Magra",IF(Cartera[[#This Row],[Tipo]]=655,"Magra",IF(Cartera[[#This Row],[Tipo]]=601,"Magra",IF(Cartera[[#This Row],[Tipo]]=751,"Galan",IF(Cartera[[#This Row],[Tipo]]=757,"Galan",IF(Cartera[[#This Row],[Tipo]]=701,"Galan",IF(Cartera[[#This Row],[Tipo]]=755,"Galan",IF(Cartera[[#This Row],[Tipo]]="CO","Conciliacion Cartera","")))))))))))))) | X16: =_xlfn.XLOOKUP(Cartera[[#This Row],[Nombre tercero]],Vendedor[Nombre],Vendedor[Vendedor],"",0,-1) -> ANGELA SILVESTRE
A17: =+A16 -> A TEAM CG SAS | B17: 151 | C17: 23474 | D17: 3 | E17: 46011.331 | F17: 46041.33 | G17: -5 | H17: 154900 | I17: 154900 | J17: 154900 | K17: 0 | L17: 0 | M17: 0 | N17: 0 | O17: 0 | P17: =SUM(Cartera[[#This Row],[1_a_8]:[>30]]) -> 0 | Q17: =+Cartera[[#This Row],[9_a_15]]+Cartera[[#This Row],[16_a_22]]+Cartera[[#This Row],[23_a_30]] -> 0 | R17: =IF(Cartera[[#This Row],[Dias]]>8,Cartera[[#This Row],[Total vencido]],0) -> 0 | S17: =IF(Cartera[[#This Row],[Mas de 9]]>0,Cartera[[#This Row],[Dias]],0) -> 0 | T17: =IF(Cartera[[#This Row],[Dias]]>99,Cartera[[#This Row],[Total vencido]],0) -> 0 | U17: =IF(Cartera[[#This Row],[Mas de 100]]>0,Cartera[[#This Row],[Dias]],0) -> 0 | V17: =Cartera[[#This Row],[Vencimiento]]-Cartera[[#This Row],[Emision]] -> 29.999792 | W17: =+IF(Cartera[[#This Row],[Tipo]]=151,"Lom",IF(Cartera[[#This Row],[Tipo]]=153,"Lom",IF(Cartera[[#This Row],[Tipo]]=155,"Lom",IF(Cartera[[#This Row],[Tipo]]=200,"Lom",IF(Cartera[[#This Row],[Tipo]]=224,"Lom",IF(Cartera[[#This Row],[Tipo]]=251,"Lom",IF(Cartera[[#This Row],[Tipo]]=651,"Magra",IF(Cartera[[#This Row],[Tipo]]=655,"Magra",IF(Cartera[[#This Row],[Tipo]]=601,"Magra",IF(Cartera[[#This Row],[Tipo]]=751,"Galan",IF(Cartera[[#This Row],[Tipo]]=757,"Galan",IF(Cartera[[#This Row],[Tipo]]=701,"Galan",IF(Cartera[[#This Row],[Tipo]]=755,"Galan",IF(Cartera[[#This Row],[Tipo]]="CO","Conciliacion Cartera","")))))))))))))) | X17: =_xlfn.XLOOKUP(Cartera[[#This Row],[Nombre tercero]],Vendedor[Nombre],Vendedor[Vendedor],"",0,-1) -> ANGELA SILVESTRE
A18: =+A17 -> A TEAM CG SAS | B18: 151 | C18: 23695 | D18: 3 | E18: 46020.184 | F18: 46050.184 | G18: -14 | H18: 219700 | I18: 219700 | J18: 219700 | K18: 0 | L18: 0 | M18: 0 | N18: 0 | O18: 0 | P18: =SUM(Cartera[[#This Row],[1_a_8]:[>30]]) -> 0 | Q18: =+Cartera[[#This Row],[9_a_15]]+Cartera[[#This Row],[16_a_22]]+Cartera[[#This Row],[23_a_30]] -> 0 | R18: =IF(Cartera[[#This Row],[Dias]]>8,Cartera[[#This Row],[Total vencido]],0) -> 0 | S18: =IF(Cartera[[#This Row],[Mas de 9]]>0,Cartera[[#This Row],[Dias]],0) -> 0 | T18: =IF(Cartera[[#This Row],[Dias]]>99,Cartera[[#This Row],[Total vencido]],0) -> 0 | U18: =IF(Cartera[[#This Row],[Mas de 100]]>0,Cartera[[#This Row],[Dias]],0) -> 0 | V18: =Cartera[[#This Row],[Vencimiento]]-Cartera[[#This Row],[Emision]] -> 29.999757 | W18: =+IF(Cartera[[#This Row],[Tipo]]=151,"Lom",IF(Cartera[[#This Row],[Tipo]]=153,"Lom",IF(Cartera[[#This Row],[Tipo]]=155,"Lom",IF(Cartera[[#This Row],[Tipo]]=200,"Lom",IF(Cartera[[#This Row],[Tipo]]=224,"Lom",IF(Cartera[[#This Row],[Tipo]]=251,"Lom",IF(Cartera[[#This Row],[Tipo]]=651,"Magra",IF(Cartera[[#This Row],[Tipo]]=655,"Magra",IF(Cartera[[#This Row],[Tipo]]=601,"Magra",IF(Cartera[[#This Row],[Tipo]]=751,"Galan",IF(Cartera[[#This Row],[Tipo]]=757,"Galan",IF(Cartera[[#This Row],[Tipo]]=701,"Galan",IF(Cartera[[#This Row],[Tipo]]=755,"Galan",IF(Cartera[[#This Row],[Tipo]]="CO","Conciliacion Cartera","")))))))))))))) | X18: =_xlfn.XLOOKUP(Cartera[[#This Row],[Nombre tercero]],Vendedor[Nombre],Vendedor[Vendedor],"",0,-1) -> ANGELA SILVESTRE
A19: ABEL Y SOFIA SAS | B19: 151 | C19: 20290 | D19: 0 | E19: 45873.302 | F19: 45903.301 | G19: 133 | H19: 114299.99 | I19: 84299.99 | J19: 0 | K19: 0 | L19: 0 | M19: 0 | N19: 0 | O19: 84299.99 | P19: =SUM(Cartera[[#This Row],[1_a_8]:[>30]]) -> 84299.99 | Q19: =+Cartera[[#This Row],[9_a_15]]+Cartera[[#This Row],[16_a_22]]+Cartera[[#This Row],[23_a_30]] -> 0 | R19: =IF(Cartera[[#This Row],[Dias]]>8,Cartera[[#This Row],[Total vencido]],0) -> 84299.99 | S19: =IF(Cartera[[#This Row],[Mas de 9]]>0,Cartera[[#This Row],[Dias]],0) -> 133 | T19: =IF(Cartera[[#This Row],[Dias]]>99,Cartera[[#This Row],[Total vencido]],0) -> 84299.99 | U19: =IF(Cartera[[#This Row],[Mas de 100]]>0,Cartera[[#This Row],[Dias]],0) -> 133 | V19: =Cartera[[#This Row],[Vencimiento]]-Cartera[[#This Row],[Emision]] -> 29.998981 | W19: =+IF(Cartera[[#This Row],[Tipo]]=151,"Lom",IF(Cartera[[#This Row],[Tipo]]=153,"Lom",IF(Cartera[[#This Row],[Tipo]]=155,"Lom",IF(Cartera[[#This Row],[Tipo]]=200,"Lom",IF(Cartera[[#This Row],[Tipo]]=224,"Lom",IF(Cartera[[#This Row],[Tipo]]=251,"Lom",IF(Cartera[[#This Row],[Tipo]]=651,"Magra",IF(Cartera[[#This Row],[Tipo]]=655,"Magra",IF(Cartera[[#This Row],[Tipo]]=601,"Magra",IF(Cartera[[#This Row],[Tipo]]=751,"Galan",IF(Cartera[[#This Row],[Tipo]]=757,"Galan",IF(Cartera[[#This Row],[Tipo]]=701,"Galan",IF(Cartera[[#This Row],[Tipo]]=755,"Galan",IF(Cartera[[#This Row],[Tipo]]="CO","Conciliacion Cartera","")))))))))))))) | X19: =_xlfn.XLOOKUP(Cartera[[#This Row],[Nombre tercero]],Vendedor[Nombre],Vendedor[Vendedor],"",0,-1) -> ANGELA SILVESTRE
A20: =+A19 -> ABEL Y SOFIA SAS | B20: 151 | C20: 21715 | D20: 0 | E20: 45945.312 | F20: 45975.312 | G20: 61 | H20: 393300 | I20: 371495 | J20: 0 | K20: 0 | L20: 0 | M20: 0 | N20: 0 | O20: 371495 | P20: =SUM(Cartera[[#This Row],[1_a_8]:[>30]]) -> 371495 | Q20: =+Cartera[[#This Row],[9_a_15]]+Cartera[[#This Row],[16_a_22]]+Cartera[[#This Row],[23_a_30]] -> 0 | R20: =IF(Cartera[[#This Row],[Dias]]>8,Cartera[[#This Row],[Total vencido]],0) -> 371495 | S20: =IF(Cartera[[#This Row],[Mas de 9]]>0,Cartera[[#This Row],[Dias]],0) -> 61 | T20: =IF(Cartera[[#This Row],[Dias]]>99,Cartera[[#This Row],[Total vencido]],0) -> 0 | U20: =IF(Cartera[[#This Row],[Mas de 100]]>0,Cartera[[#This Row],[Dias]],0) -> 0 | V20: =Cartera[[#This Row],[Vencimiento]]-Cartera[[#This Row],[Emision]] -> 29.99985 | W20: =+IF(Cartera[[#This Row],[Tipo]]=151,"Lom",IF(Cartera[[#This Row],[Tipo]]=153,"Lom",IF(Cartera[[#This Row],[Tipo]]=155,"Lom",IF(Cartera[[#This Row],[Tipo]]=200,"Lom",IF(Cartera[[#This Row],[Tipo]]=224,"Lom",IF(Cartera[[#This Row],[Tipo]]=251,"Lom",IF(Cartera[[#This Row],[Tipo]]=651,"Magra",IF(Cartera[[#This Row],[Tipo]]=655,"Magra",IF(Cartera[[#This Row],[Tipo]]=601,"Magra",IF(Cartera[[#This Row],[Tipo]]=751,"Galan",IF(Cartera[[#This Row],[Tipo]]=757,"Galan",IF(Cartera[[#This Row],[Tipo]]=701,"Galan",IF(Cartera[[#This Row],[Tipo]]=755,"Galan",IF(Cartera[[#This Row],[Tipo]]="CO","Conciliacion Cartera","")))))))))))))) | X20: =_xlfn.XLOOKUP(Cartera[[#This Row],[Nombre tercero]],Vendedor[Nombre],Vendedor[Vendedor],"",0,-1) -> ANGELA SILVESTRE
A21: =+A20 -> ABEL Y SOFIA SAS | B21: 151 | C21: 22119 | D21: 0 | E21: 45962.307 | F21: 45992.307 | G21: 44 | H21: 1772250 | I21: 1772250 | J21: 0 | K21: 0 | L21: 0 | M21: 0 | N21: 0 | O21: 1772250 | P21: =SUM(Cartera[[#This Row],[1_a_8]:[>30]]) -> 1772250 | Q21: =+Cartera[[#This Row],[9_a_15]]+Cartera[[#This Row],[16_a_22]]+Cartera[[#This Row],[23_a_30]] -> 0 | R21: =IF(Cartera[[#This Row],[Dias]]>8,Cartera[[#This Row],[Total vencido]],0) -> 1772250 | S21: =IF(Cartera[[#This Row],[Mas de 9]]>0,Cartera[[#This Row],[Dias]],0) -> 44 | T21: =IF(Cartera[[#This Row],[Dias]]>99,Cartera[[#This Row],[Total vencido]],0) -> 0 | U21: =IF(Cartera[[#This Row],[Mas de 100]]>0,Cartera[[#This Row],[Dias]],0) -> 0 | V21: =Cartera[[#This Row],[Vencimiento]]-Cartera[[#This Row],[Emision]] -> 29.999896 | W21: =+IF(Cartera[[#This Row],[Tipo]]=151,"Lom",IF(Cartera[[#This Row],[Tipo]]=153,"Lom",IF(Cartera[[#This Row],[Tipo]]=155,"Lom",IF(Cartera[[#This Row],[Tipo]]=200,"Lom",IF(Cartera[[#This Row],[Tipo]]=224,"Lom",IF(Cartera[[#This Row],[Tipo]]=251,"Lom",IF(Cartera[[#This Row],[Tipo]]=651,"Magra",IF(Cartera[[#This Row],[Tipo]]=655,"Magra",IF(Cartera[[#This Row],[Tipo]]=601,"Magra",IF(Cartera[[#This Row],[Tipo]]=751,"Galan",IF(Cartera[[#This Row],[Tipo]]=757,"Galan",IF(Cartera[[#This Row],[Tipo]]=701,"Galan",IF(Cartera[[#This Row],[Tipo]]=755,"Galan",IF(Cartera[[#This Row],[Tipo]]="CO","Conciliacion Cartera","")))))))))))))) | X21: =_xlfn.XLOOKUP(Cartera[[#This Row],[Nombre tercero]],Vendedor[Nombre],Vendedor[Vendedor],"",0,-1) -> ANGELA SILVESTRE
A22: =+A21 -> ABEL Y SOFIA SAS | B22: 151 | C22: 22121 | D22: 0 | E22: 45962.31 | F22: 45992.31 | G22: 44 | H22: 487600 | I22: 487600 | J22: 0 | K22: 0 | L22: 0 | M22: 0 | N22: 0 | O22: 487600 | P22: =SUM(Cartera[[#This Row],[1_a_8]:[>30]]) -> 487600 | Q22: =+Cartera[[#This Row],[9_a_15]]+Cartera[[#This Row],[16_a_22]]+Cartera[[#This Row],[23_a_30]] -> 0 | R22: =IF(Cartera[[#This Row],[Dias]]>8,Cartera[[#This Row],[Total vencido]],0) -> 487600 | S22: =IF(Cartera[[#This Row],[Mas de 9]]>0,Cartera[[#This Row],[Dias]],0) -> 44 | T22: =IF(Cartera[[#This Row],[Dias]]>99,Cartera[[#This Row],[Total vencido]],0) -> 0 | U22: =IF(Cartera[[#This Row],[Mas de 100]]>0,Cartera[[#This Row],[Dias]],0) -> 0 | V22: =Cartera[[#This Row],[Vencimiento]]-Cartera[[#This Row],[Emision]] -> 29.999884 | W22: =+IF(Cartera[[#This Row],[Tipo]]=151,"Lom",IF(Cartera[[#This Row],[Tipo]]=153,"Lom",IF(Cartera[[#This Row],[Tipo]]=155,"Lom",IF(Cartera[[#This Row],[Tipo]]=200,"Lom",IF(Cartera[[#This Row],[Tipo]]=224,"Lom",IF(Cartera[[#This Row],[Tipo]]=251,"Lom",IF(Cartera[[#This Row],[Tipo]]=651,"Magra",IF(Cartera[[#This Row],[Tipo]]=655,"Magra",IF(Cartera[[#This Row],[Tipo]]=601,"Magra",IF(Cartera[[#This Row],[Tipo]]=751,"Galan",IF(Cartera[[#This Row],[Tipo]]=757,"Galan",IF(Cartera[[#This Row],[Tipo]]=701,"Galan",IF(Cartera[[#This Row],[Tipo]]=755,"Galan",IF(Cartera[[#This Row],[Tipo]]="CO","Conciliacion Cartera","")))))))))))))) | X22: =_xlfn.XLOOKUP(Cartera[[#This Row],[Nombre tercero]],Vendedor[Nombre],Vendedor[Vendedor],"",0,-1) -> ANGELA SILVESTRE
A23: =+A22 -> ABEL Y SOFIA SAS | B23: 151 | C23: 22124 | D23: 0 | E23: 45962.317 | F23: 45992.317 | G23: 44 | H23: 150800 | I23: 150800 | J23: 0 | K23: 0 | L23: 0 | M23: 0 | N23: 0 | O23: 150800 | P23: =SUM(Cartera[[#This Row],[1_a_8]:[>30]]) -> 150800 | Q23: =+Cartera[[#This Row],[9_a_15]]+Cartera[[#This Row],[16_a_22]]+Cartera[[#This Row],[23_a_30]] -> 0 | R23: =IF(Cartera[[#This Row],[Dias]]>8,Cartera[[#This Row],[Total vencido]],0) -> 150800 | S23: =IF(Cartera[[#This Row],[Mas de 9]]>0,Cartera[[#This Row],[Dias]],0) -> 44 | T23: =IF(Cartera[[#This Row],[Dias]]>99,Cartera[[#This Row],[Total vencido]],0) -> 0 | U23: =IF(Cartera[[#This Row],[Mas de 100]]>0,Cartera[[#This Row],[Dias]],0) -> 0 | V23: =Cartera[[#This Row],[Vencimiento]]-Cartera[[#This Row],[Emision]] -> 29.999861 | W23: =+IF(Cartera[[#This Row],[Tipo]]=151,"Lom",IF(Cartera[[#This Row],[Tipo]]=153,"Lom",IF(Cartera[[#This Row],[Tipo]]=155,"Lom",IF(Cartera[[#This Row],[Tipo]]=200,"Lom",IF(Cartera[[#This Row],[Tipo]]=224,"Lom",IF(Cartera[[#This Row],[Tipo]]=251,"Lom",IF(Cartera[[#This Row],[Tipo]]=651,"Magra",IF(Cartera[[#This Row],[Tipo]]=655,"Magra",IF(Cartera[[#This Row],[Tipo]]=601,"Magra",IF(Cartera[[#This Row],[Tipo]]=751,"Galan",IF(Cartera[[#This Row],[Tipo]]=757,"Galan",IF(Cartera[[#This Row],[Tipo]]=701,"Galan",IF(Cartera[[#This Row],[Tipo]]=755,"Galan",IF(Cartera[[#This Row],[Tipo]]="CO","Conciliacion Cartera","")))))))))))))) | X23: =_xlfn.XLOOKUP(Cartera[[#This Row],[Nombre tercero]],Vendedor[Nombre],Vendedor[Vendedor],"",0,-1) -> ANGELA SILVESTRE
A24: =+A23 -> ABEL Y SOFIA SAS | B24: 151 | C24: 22125 | D24: 0 | E24: 45962.318 | F24: 45992.317 | G24: 44 | H24: 343300 | I24: 343300 | J24: 0 | K24: 0 | L24: 0 | M24: 0 | N24: 0 | O24: 343300 | P24: =SUM(Cartera[[#This Row],[1_a_8]:[>30]]) -> 343300 | Q24: =+Cartera[[#This Row],[9_a_15]]+Cartera[[#This Row],[16_a_22]]+Cartera[[#This Row],[23_a_30]] -> 0 | R24: =IF(Cartera[[#This Row],[Dias]]>8,Cartera[[#This Row],[Total vencido]],0) -> 343300 | S24: =IF(Cartera[[#This Row],[Mas de 9]]>0,Cartera[[#This Row],[Dias]],0) -> 44 | T24: =IF(Cartera[[#This Row],[Dias]]>99,Cartera[[#This Row],[Total vencido]],0) -> 0 | U24: =IF(Cartera[[#This Row],[Mas de 100]]>0,Cartera[[#This Row],[Dias]],0) -> 0 | V24: =Cartera[[#This Row],[Vencimiento]]-Cartera[[#This Row],[Emision]] -> 29.999687 | W24: =+IF(Cartera[[#This Row],[Tipo]]=151,"Lom",IF(Cartera[[#This Row],[Tipo]]=153,"Lom",IF(Cartera[[#This Row],[Tipo]]=155,"Lom",IF(Cartera[[#This Row],[Tipo]]=200,"Lom",IF(Cartera[[#This Row],[Tipo]]=224,"Lom",IF(Cartera[[#This Row],[Tipo]]=251,"Lom",IF(Cartera[[#This Row],[Tipo]]=651,"Magra",IF(Cartera[[#This Row],[Tipo]]=655,"Magra",IF(Cartera[[#This Row],[Tipo]]=601,"Magra",IF(Cartera[[#This Row],[Tipo]]=751,"Galan",IF(Cartera[[#This Row],[Tipo]]=757,"Galan",IF(Cartera[[#This Row],[Tipo]]=701,"Galan",IF(Cartera[[#This Row],[Tipo]]=755,"Galan",IF(Cartera[[#This Row],[Tipo]]="CO","Conciliacion Cartera","")))))))))))))) | X24: =_xlfn.XLOOKUP(Cartera[[#This Row],[Nombre tercero]],Vendedor[Nombre],Vendedor[Vendedor],"",0,-1) -> ANGELA SILVESTRE
A25: =+A24 -> ABEL Y SOFIA SAS | B25: 151 | C25: 22131 | D25: 0 | E25: 45962.377 | F25: 45992.377 | G25: 44 | H25: 1200000 | I25: 1200000 | J25: 0 | K25: 0 | L25: 0 | M25: 0 | N25: 0 | O25: 1200000 | P25: =SUM(Cartera[[#This Row],[1_a_8]:[>30]]) -> 1200000 | Q25: =+Cartera[[#This Row],[9_a_15]]+Cartera[[#This Row],[16_a_22]]+Cartera[[#This Row],[23_a_30]] -> 0 | R25: =IF(Cartera[[#This Row],[Dias]]>8,Cartera[[#This Row],[Total vencido]],0) -> 1200000 | S25: =IF(Cartera[[#This Row],[Mas de 9]]>0,Cartera[[#This Row],[Dias]],0) -> 44 | T25: =IF(Cartera[[#This Row],[Dias]]>99,Cartera[[#This Row],[Total vencido]],0) -> 0 | U25: =IF(Cartera[[#This Row],[Mas de 100]]>0,Cartera[[#This Row],[Dias]],0) -> 0 | V25: =Cartera[[#This Row],[Vencimiento]]-Cartera[[#This Row],[Emision]] -> 29.999537 | W25: =+IF(Cartera[[#This Row],[Tipo]]=151,"Lom",IF(Cartera[[#This Row],[Tipo]]=153,"Lom",IF(Cartera[[#This Row],[Tipo]]=155,"Lom",IF(Cartera[[#This Row],[Tipo]]=200,"Lom",IF(Cartera[[#This Row],[Tipo]]=224,"Lom",IF(Cartera[[#This Row],[Tipo]]=251,"Lom",IF(Cartera[[#This Row],[Tipo]]=651,"Magra",IF(Cartera[[#This Row],[Tipo]]=655,"Magra",IF(Cartera[[#This Row],[Tipo]]=601,"Magra",IF(Cartera[[#This Row],[Tipo]]=751,"Galan",IF(Cartera[[#This Row],[Tipo]]=757,"Galan",IF(Cartera[[#This Row],[Tipo]]=701,"Galan",IF(Cartera[[#This Row],[Tipo]]=755,"Galan",IF(Cartera[[#This Row],[Tipo]]="CO","Conciliacion Cartera","")))))))))))))) | X25: =_xlfn.XLOOKUP(Cartera[[#This Row],[Nombre tercero]],Vendedor[Nombre],Vendedor[Vendedor],"",0,-1) -> ANGELA SILVESTRE
A26: =+A25 -> ABEL Y SOFIA SAS | B26: 151 | C26: 22151 | D26: 0 | E26: 45965.291 | F26: 45995.287 | G26: 41 | H26: 195999.97 | I26: 195999.97 | J26: 0 | K26: 0 | L26: 0 | M26: 0 | N26: 0 | O26: 195999.97 | P26: =SUM(Cartera[[#This Row],[1_a_8]:[>30]]) -> 195999.97 | Q26: =+Cartera[[#This Row],[9_a_15]]+Cartera[[#This Row],[16_a_22]]+Cartera[[#This Row],[23_a_30]] -> 0 | R26: =IF(Cartera[[#This Row],[Dias]]>8,Cartera[[#This Row],[Total vencido]],0) -> 195999.97 | S26: =IF(Cartera[[#This Row],[Mas de 9]]>0,Cartera[[#This Row],[Dias]],0) -> 41 | T26: =IF(Cartera[[#This Row],[Dias]]>99,Cartera[[#This Row],[Total vencido]],0) -> 0 | U26: =IF(Cartera[[#This Row],[Mas de 100]]>0,Cartera[[#This Row],[Dias]],0) -> 0 | V26: =Cartera[[#This Row],[Vencimiento]]-Cartera[[#This Row],[Emision]] -> 29.996343 | W26: =+IF(Cartera[[#This Row],[Tipo]]=151,"Lom",IF(Cartera[[#This Row],[Tipo]]=153,"Lom",IF(Cartera[[#This Row],[Tipo]]=155,"Lom",IF(Cartera[[#This Row],[Tipo]]=200,"Lom",IF(Cartera[[#This Row],[Tipo]]=224,"Lom",IF(Cartera[[#This Row],[Tipo]]=251,"Lom",IF(Cartera[[#This Row],[Tipo]]=651,"Magra",IF(Cartera[[#This Row],[Tipo]]=655,"Magra",IF(Cartera[[#This Row],[Tipo]]=601,"Magra",IF(Cartera[[#This Row],[Tipo]]=751,"Galan",IF(Cartera[[#This Row],[Tipo]]=757,"Galan",IF(Cartera[[#This Row],[Tipo]]=701,"Galan",IF(Cartera[[#This Row],[Tipo]]=755,"Galan",IF(Cartera[[#This Row],[Tipo]]="CO","Conciliacion Cartera","")))))))))))))) | X26: =_xlfn.XLOOKUP(Cartera[[#This Row],[Nombre tercero]],Vendedor[Nombre],Vendedor[Vendedor],"",0,-1) -> ANGELA SILVESTRE
A27: =+A26 -> ABEL Y SOFIA SAS | B27: 151 | C27: 22152 | D27: 0 | E27: 45965.293 | F27: 45995.292 | G27: 41 | H27: 82899.99 | I27: 82899.99 | J27: 0 | K27: 0 | L27: 0 | M27: 0 | N27: 0 | O27: 82899.99 | P27: =SUM(Cartera[[#This Row],[1_a_8]:[>30]]) -> 82899.99 | Q27: =+Cartera[[#This Row],[9_a_15]]+Cartera[[#This Row],[16_a_22]]+Cartera[[#This Row],[23_a_30]] -> 0 | R27: =IF(Cartera[[#This Row],[Dias]]>8,Cartera[[#This Row],[Total vencido]],0) -> 82899.99 | S27: =IF(Cartera[[#This Row],[Mas de 9]]>0,Cartera[[#This Row],[Dias]],0) -> 41 | T27: =IF(Cartera[[#This Row],[Dias]]>99,Cartera[[#This Row],[Total vencido]],0) -> 0 | U27: =IF(Cartera[[#This Row],[Mas de 100]]>0,Cartera[[#This Row],[Dias]],0) -> 0 | V27: =Cartera[[#This Row],[Vencimiento]]-Cartera[[#This Row],[Emision]] -> 29.999155 | W27: =+IF(Cartera[[#This Row],[Tipo]]=151,"Lom",IF(Cartera[[#This Row],[Tipo]]=153,"Lom",IF(Cartera[[#This Row],[Tipo]]=155,"Lom",IF(Cartera[[#This Row],[Tipo]]=200,"Lom",IF(Cartera[[#This Row],[Tipo]]=224,"Lom",IF(Cartera[[#This Row],[Tipo]]=251,"Lom",IF(Cartera[[#This Row],[Tipo]]=651,"Magra",IF(Cartera[[#This Row],[Tipo]]=655,"Magra",IF(Cartera[[#This Row],[Tipo]]=601,"Magra",IF(Cartera[[#This Row],[Tipo]]=751,"Galan",IF(Cartera[[#This Row],[Tipo]]=757,"Galan",IF(Cartera[[#This Row],[Tipo]]=701,"Galan",IF(Cartera[[#This Row],[Tipo]]=755,"Galan",IF(Cartera[[#This Row],[Tipo]]="CO","Conciliacion Cartera","")))))))))))))) | X27: =_xlfn.XLOOKUP(Cartera[[#This Row],[Nombre tercero]],Vendedor[Nombre],Vendedor[Vendedor],"",0,-1) -> ANGELA SILVESTRE
A28: =+A27 -> ABEL Y SOFIA SAS | B28: 151 | C28: 22173 | D28: 0 | E28: 45966.285 | F28: 45996.284 | G28: 40 | H28: 178899.99 | I28: 178899.99 | J28: 0 | K28: 0 | L28: 0 | M28: 0 | N28: 0 | O28: 178899.99 | P28: =SUM(Cartera[[#This Row],[1_a_8]:[>30]]) -> 178899.99 | Q28: =+Cartera[[#This Row],[9_a_15]]+Cartera[[#This Row],[16_a_22]]+Cartera[[#This Row],[23_a_30]] -> 0 | R28: =IF(Cartera[[#This Row],[Dias]]>8,Cartera[[#This Row],[Total vencido]],0) -> 178899.99 | S28: =IF(Cartera[[#This Row],[Mas de 9]]>0,Cartera[[#This Row],[Dias]],0) -> 40 | T28: =IF(Cartera[[#This Row],[Dias]]>99,Cartera[[#This Row],[Total vencido]],0) -> 0 | U28: =IF(Cartera[[#This Row],[Mas de 100]]>0,Cartera[[#This Row],[Dias]],0) -> 0 | V28: =Cartera[[#This Row],[Vencimiento]]-Cartera[[#This Row],[Emision]] -> 29.999213 | W28: =+IF(Cartera[[#This Row],[Tipo]]=151,"Lom",IF(Cartera[[#This Row],[Tipo]]=153,"Lom",IF(Cartera[[#This Row],[Tipo]]=155,"Lom",IF(Cartera[[#This Row],[Tipo]]=200,"Lom",IF(Cartera[[#This Row],[Tipo]]=224,"Lom",IF(Cartera[[#This Row],[Tipo]]=251,"Lom",IF(Cartera[[#This Row],[Tipo]]=651,"Magra",IF(Cartera[[#This Row],[Tipo]]=655,"Magra",IF(Cartera[[#This Row],[Tipo]]=601,"Magra",IF(Cartera[[#This Row],[Tipo]]=751,"Galan",IF(Cartera[[#This Row],[Tipo]]=757,"Galan",IF(Cartera[[#This Row],[Tipo]]=701,"Galan",IF(Cartera[[#This Row],[Tipo]]=755,"Galan",IF(Cartera[[#This Row],[Tipo]]="CO","Conciliacion Cartera","")))))))))))))) | X28: =_xlfn.XLOOKUP(Cartera[[#This Row],[Nombre tercero]],Vendedor[Nombre],Vendedor[Vendedor],"",0,-1) -> ANGELA SILVESTRE
A29: =+A28 -> ABEL Y SOFIA SAS | B29: 151 | C29: 22174 | D29: 0 | E29: 45966.287 | F29: 45996.286 | G29: 40 | H29: 415850 | I29: 415850 | J29: 0 | K29: 0 | L29: 0 | M29: 0 | N29: 0 | O29: 415850 | P29: =SUM(Cartera[[#This Row],[1_a_8]:[>30]]) -> 415850 | Q29: =+Cartera[[#This Row],[9_a_15]]+Cartera[[#This Row],[16_a_22]]+Cartera[[#This Row],[23_a_30]] -> 0 | R29: =IF(Cartera[[#This Row],[Dias]]>8,Cartera[[#This Row],[Total vencido]],0) -> 415850 | S29: =IF(Cartera[[#This Row],[Mas de 9]]>0,Cartera[[#This Row],[Dias]],0) -> 40 | T29: =IF(Cartera[[#This Row],[Dias]]>99,Cartera[[#This Row],[Total vencido]],0) -> 0 | U29: =IF(Cartera[[#This Row],[Mas de 100]]>0,Cartera[[#This Row],[Dias]],0) -> 0 | V29: =Cartera[[#This Row],[Vencimiento]]-Cartera[[#This Row],[Emision]] -> 29.99985 | W29: =+IF(Cartera[[#This Row],[Tipo]]=151,"Lom",IF(Cartera[[#This Row],[Tipo]]=153,"Lom",IF(Cartera[[#This Row],[Tipo]]=155,"Lom",IF(Cartera[[#This Row],[Tipo]]=200,"Lom",IF(Cartera[[#This Row],[Tipo]]=224,"Lom",IF(Cartera[[#This Row],[Tipo]]=251,"Lom",IF(Cartera[[#This Row],[Tipo]]=651,"Magra",IF(Cartera[[#This Row],[Tipo]]=655,"Magra",IF(Cartera[[#This Row],[Tipo]]=601,"Magra",IF(Cartera[[#This Row],[Tipo]]=751,"Galan",IF(Cartera[[#This Row],[Tipo]]=757,"Galan",IF(Cartera[[#This Row],[Tipo]]=701,"Galan",IF(Cartera[[#This Row],[Tipo]]=755,"Galan",IF(Cartera[[#This Row],[Tipo]]="CO","Conciliacion Cartera","")))))))))))))) | X29: =_xlfn.XLOOKUP(Cartera[[#This Row],[Nombre tercero]],Vendedor[Nombre],Vendedor[Vendedor],"",0,-1) -> ANGELA SILVESTRE
A30: =+A29 -> ABEL Y SOFIA SAS | B30: 151 | C30: 22176 | D30: 0 | E30: 45966.288 | F30: 45996.288 | G30: 40 | H30: 342200 | I30: 342200 | J30: 0 | K30: 0 | L30: 0 | M30: 0 | N30: 0 | O30: 342200 | P30: =SUM(Cartera[[#This Row],[1_a_8]:[>30]]) -> 342200 | Q30: =+Cartera[[#This Row],[9_a_15]]+Cartera[[#This Row],[16_a_22]]+Cartera[[#This Row],[23_a_30]] -> 0 | R30: =IF(Cartera[[#This Row],[Dias]]>8,Cartera[[#This Row],[Total vencido]],0) -> 342200 | S30: =IF(Cartera[[#This Row],[Mas de 9]]>0,Cartera[[#This Row],[Dias]],0) -> 40 | T30: =IF(Cartera[[#This Row],[Dias]]>99,Cartera[[#This Row],[Total vencido]],0) -> 0 | U30: =IF(Cartera[[#This Row],[Mas de 100]]>0,Cartera[[#This Row],[Dias]],0) -> 0 | V30: =Cartera[[#This Row],[Vencimiento]]-Cartera[[#This Row],[Emision]] -> 29.999792 | W30: =+IF(Cartera[[#This Row],[Tipo]]=151,"Lom",IF(Cartera[[#This Row],[Tipo]]=153,"Lom",IF(Cartera[[#This Row],[Tipo]]=155,"Lom",IF(Cartera[[#This Row],[Tipo]]=200,"Lom",IF(Cartera[[#This Row],[Tipo]]=224,"Lom",IF(Cartera[[#This Row],[Tipo]]=251,"Lom",IF(Cartera[[#This Row],[Tipo]]=651,"Magra",IF(Cartera[[#This Row],[Tipo]]=655,"Magra",IF(Cartera[[#This Row],[Tipo]]=601,"Magra",IF(Cartera[[#This Row],[Tipo]]=751,"Galan",IF(Cartera[[#This Row],[Tipo]]=757,"Galan",IF(Cartera[[#This Row],[Tipo]]=701,"Galan",IF(Cartera[[#This Row],[Tipo]]=755,"Galan",IF(Cartera[[#This Row],[Tipo]]="CO","Conciliacion Cartera","")))))))))))))) | X30: =_xlfn.XLOOKUP(Cartera[[#This Row],[Nombre tercero]],Vendedor[Nombre],Vendedor[Vendedor],"",0,-1) -> ANGELA SILVESTRE
A31: =+A30 -> ABEL Y SOFIA SAS | B31: 151 | C31: 22177 | D31: 0 | E31: 45966.289 | F31: 45996.289 | G31: 40 | H31: 615500 | I31: 615500 | J31: 0 | K31: 0 | L31: 0 | M31: 0 | N31: 0 | O31: 615500 | P31: =SUM(Cartera[[#This Row],[1_a_8]:[>30]]) -> 615500 | Q31: =+Cartera[[#This Row],[9_a_15]]+Cartera[[#This Row],[16_a_22]]+Cartera[[#This Row],[23_a_30]] -> 0 | R31: =IF(Cartera[[#This Row],[Dias]]>8,Cartera[[#This Row],[Total vencido]],0) -> 615500 | S31: =IF(Cartera[[#This Row],[Mas de 9]]>0,Cartera[[#This Row],[Dias]],0) -> 40 | T31: =IF(Cartera[[#This Row],[Dias]]>99,Cartera[[#This Row],[Total vencido]],0) -> 0 | U31: =IF(Cartera[[#This Row],[Mas de 100]]>0,Cartera[[#This Row],[Dias]],0) -> 0 | V31: =Cartera[[#This Row],[Vencimiento]]-Cartera[[#This Row],[Emision]] -> 29.99985 | W31: =+IF(Cartera[[#This Row],[Tipo]]=151,"Lom",IF(Cartera[[#This Row],[Tipo]]=153,"Lom",IF(Cartera[[#This Row],[Tipo]]=155,"Lom",IF(Cartera[[#This Row],[Tipo]]=200,"Lom",IF(Cartera[[#This Row],[Tipo]]=224,"Lom",IF(Cartera[[#This Row],[Tipo]]=251,"Lom",IF(Cartera[[#This Row],[Tipo]]=651,"Magra",IF(Cartera[[#This Row],[Tipo]]=655,"Magra",IF(Cartera[[#This Row],[Tipo]]=601,"Magra",IF(Cartera[[#This Row],[Tipo]]=751,"Galan",IF(Cartera[[#This Row],[Tipo]]=757,"Galan",IF(Cartera[[#This Row],[Tipo]]=701,"Galan",IF(Cartera[[#This Row],[Tipo]]=755,"Galan",IF(Cartera[[#This Row],[Tipo]]="CO","Conciliacion Cartera","")))))))))))))) | X31: =_xlfn.XLOOKUP(Cartera[[#This Row],[Nombre tercero]],Vendedor[Nombre],Vendedor[Vendedor],"",0,-1) -> ANGELA SILVESTRE
... A190: =+A189 -> ABEL Y SOFIA SAS | B190: 151 | C190: 23737 | D190: 0 | E190: 46021.345 | F190: 46051.344 | G190: -15 | H190: 1816900 | I190: 1816900 | J190: 1816900 | K190: 0 | L190: 0 | M190: 0 | N190: 0 | O190: 0 | P190: =SUM(Cartera[[#This Row],[1_a_8]:[>30]]) -> 0 | Q190: =+Cartera[[#This Row],[9_a_15]]+Cartera[[#This Row],[16_a_22]]+Cartera[[#This Row],[23_a_30]] -> 0 | R190: =IF(Cartera[[#This Row],[Dias]]>8,Cartera[[#This Row],[Total vencido]],0) -> 0 | S190: =IF(Cartera[[#This Row],[Mas de 9]]>0,Cartera[[#This Row],[Dias]],0) -> 0 | T190: =IF(Cartera[[#This Row],[Dias]]>99,Cartera[[#This Row],[Total vencido]],0) -> 0 | U190: =IF(Cartera[[#This Row],[Mas de 100]]>0,Cartera[[#This Row],[Dias]],0) -> 0 | V190: =Cartera[[#This Row],[Vencimiento]]-Cartera[[#This Row],[Emision]] -> 29.999016 | W190: =+IF(Cartera[[#This Row],[Tipo]]=151,"Lom",IF(Cartera[[#This Row],[Tipo]]=153,"Lom",IF(Cartera[[#This Row],[Tipo]]=155,"Lom",IF(Cartera[[#This Row],[Tipo]]=200,"Lom",IF(Cartera[[#This Row],[Tipo]]=224,"Lom",IF(Cartera[[#This Row],[Tipo]]=251,"Lom",IF(Cartera[[#This Row],[Tipo]]=651,"Magra",IF(Cartera[[#This Row],[Tipo]]=655,"Magra",IF(Cartera[[#This Row],[Tipo]]=601,"Magra",IF(Cartera[[#This Row],[Tipo]]=751,"Galan",IF(Cartera[[#This Row],[Tipo]]=757,"Galan",IF(Cartera[[#This Row],[Tipo]]=701,"Galan",IF(Cartera[[#This Row],[Tipo]]=755,"Galan",IF(Cartera[[#This Row],[Tipo]]="CO","Conciliacion Cartera","")))))))))))))) | X190: =_xlfn.XLOOKUP(Cartera[[#This Row],[Nombre tercero]],Vendedor[Nombre],Vendedor[Vendedor],"",0,-1) -> ANGELA SILVESTRE
A191: ADRIANA BERMUDEZ RAMIREZ | B191: 751 | C191: 15707 | D191: 1 | E191: 45910.513 | F191: 45918.513 | G191: 118 | H191: 862400 | I191: 231640 | J191: 0 | K191: 0 | L191: 0 | M191: 0 | N191: 0 | O191: 231640 | P191: =SUM(Cartera[[#This Row],[1_a_8]:[>30]]) -> 231640 | Q191: =+Cartera[[#This Row],[9_a_15]]+Cartera[[#This Row],[16_a_22]]+Cartera[[#This Row],[23_a_30]] -> 0 | R191: =IF(Cartera[[#This Row],[Dias]]>8,Cartera[[#This Row],[Total vencido]],0) -> 231640 | S191: =IF(Cartera[[#This Row],[Mas de 9]]>0,Cartera[[#This Row],[Dias]],0) -> 118 | T191: =IF(Cartera[[#This Row],[Dias]]>99,Cartera[[#This Row],[Total vencido]],0) -> 231640 | U191: =IF(Cartera[[#This Row],[Mas de 100]]>0,Cartera[[#This Row],[Dias]],0) -> 118 | V191: =Cartera[[#This Row],[Vencimiento]]-Cartera[[#This Row],[Emision]] -> 7.999838 | W191: =+IF(Cartera[[#This Row],[Tipo]]=151,"Lom",IF(Cartera[[#This Row],[Tipo]]=153,"Lom",IF(Cartera[[#This Row],[Tipo]]=155,"Lom",IF(Cartera[[#This Row],[Tipo]]=200,"Lom",IF(Cartera[[#This Row],[Tipo]]=224,"Lom",IF(Cartera[[#This Row],[Tipo]]=251,"Lom",IF(Cartera[[#This Row],[Tipo]]=651,"Magra",IF(Cartera[[#This Row],[Tipo]]=655,"Magra",IF(Cartera[[#This Row],[Tipo]]=601,"Magra",IF(Cartera[[#This Row],[Tipo]]=751,"Galan",IF(Cartera[[#This Row],[Tipo]]=757,"Galan",IF(Cartera[[#This Row],[Tipo]]=701,"Galan",IF(Cartera[[#This Row],[Tipo]]=755,"Galan",IF(Cartera[[#This Row],[Tipo]]="CO","Conciliacion Cartera","")))))))))))))) | X191: =_xlfn.XLOOKUP(Cartera[[#This Row],[Nombre tercero]],Vendedor[Nombre],Vendedor[Vendedor],"",0,-1) -> JORGE PARDO
A192: =+A191 -> ADRIANA BERMUDEZ RAMIREZ | B192: 751 | C192: 18788 | D192: 1 | E192: 46013.475 | F192: 46021.475 | G192: 15 | H192: 319200 | I192: 319200 | J192: 0 | K192: 0 | L192: 319200 | M192: 0 | N192: 0 | O192: 0 | P192: =SUM(Cartera[[#This Row],[1_a_8]:[>30]]) -> 319200 | Q192: =+Cartera[[#This Row],[9_a_15]]+Cartera[[#This Row],[16_a_22]]+Cartera[[#This Row],[23_a_30]] -> 319200 | R192: =IF(Cartera[[#This Row],[Dias]]>8,Cartera[[#This Row],[Total vencido]],0) -> 319200 | S192: =IF(Cartera[[#This Row],[Mas de 9]]>0,Cartera[[#This Row],[Dias]],0) -> 15 | T192: =IF(Cartera[[#This Row],[Dias]]>99,Cartera[[#This Row],[Total vencido]],0) -> 0 | U192: =IF(Cartera[[#This Row],[Mas de 100]]>0,Cartera[[#This Row],[Dias]],0) -> 0 | V192: =Cartera[[#This Row],[Vencimiento]]-Cartera[[#This Row],[Emision]] -> 7.9998843 | W192: =+IF(Cartera[[#This Row],[Tipo]]=151,"Lom",IF(Cartera[[#This Row],[Tipo]]=153,"Lom",IF(Cartera[[#This Row],[Tipo]]=155,"Lom",IF(Cartera[[#This Row],[Tipo]]=200,"Lom",IF(Cartera[[#This Row],[Tipo]]=224,"Lom",IF(Cartera[[#This Row],[Tipo]]=251,"Lom",IF(Cartera[[#This Row],[Tipo]]=651,"Magra",IF(Cartera[[#This Row],[Tipo]]=655,"Magra",IF(Cartera[[#This Row],[Tipo]]=601,"Magra",IF(Cartera[[#This Row],[Tipo]]=751,"Galan",IF(Cartera[[#This Row],[Tipo]]=757,"Galan",IF(Cartera[[#This Row],[Tipo]]=701,"Galan",IF(Cartera[[#This Row],[Tipo]]=755,"Galan",IF(Cartera[[#This Row],[Tipo]]="CO","Conciliacion Cartera","")))))))))))))) | X192: =_xlfn.XLOOKUP(Cartera[[#This Row],[Nombre tercero]],Vendedor[Nombre],Vendedor[Vendedor],"",0,-1) -> JORGE PARDO
A193: =+A192 -> ADRIANA BERMUDEZ RAMIREZ | B193: 751 | C193: 18809 | D193: 1 | E193: 46013.571 | F193: 46021.571 | G193: 15 | H193: 1454000 | I193: 1454000 | J193: 0 | K193: 0 | L193: 1454000 | M193: 0 | N193: 0 | O193: 0 | P193: =SUM(Cartera[[#This Row],[1_a_8]:[>30]]) -> 1454000 | Q193: =+Cartera[[#This Row],[9_a_15]]+Cartera[[#This Row],[16_a_22]]+Cartera[[#This Row],[23_a_30]] -> 1454000 | R193: =IF(Cartera[[#This Row],[Dias]]>8,Cartera[[#This Row],[Total vencido]],0) -> 1454000 | S193: =IF(Cartera[[#This Row],[Mas de 9]]>0,Cartera[[#This Row],[Dias]],0) -> 15 | T193: =IF(Cartera[[#This Row],[Dias]]>99,Cartera[[#This Row],[Total vencido]],0) -> 0 | U193: =IF(Cartera[[#This Row],[Mas de 100]]>0,Cartera[[#This Row],[Dias]],0) -> 0 | V193: =Cartera[[#This Row],[Vencimiento]]-Cartera[[#This Row],[Emision]] -> 7.9997685 | W193: =+IF(Cartera[[#This Row],[Tipo]]=151,"Lom",IF(Cartera[[#This Row],[Tipo]]=153,"Lom",IF(Cartera[[#This Row],[Tipo]]=155,"Lom",IF(Cartera[[#This Row],[Tipo]]=200,"Lom",IF(Cartera[[#This Row],[Tipo]]=224,"Lom",IF(Cartera[[#This Row],[Tipo]]=251,"Lom",IF(Cartera[[#This Row],[Tipo]]=651,"Magra",IF(Cartera[[#This Row],[Tipo]]=655,"Magra",IF(Cartera[[#This Row],[Tipo]]=601,"Magra",IF(Cartera[[#This Row],[Tipo]]=751,"Galan",IF(Cartera[[#This Row],[Tipo]]=757,"Galan",IF(Cartera[[#This Row],[Tipo]]=701,"Galan",IF(Cartera[[#This Row],[Tipo]]=755,"Galan",IF(Cartera[[#This Row],[Tipo]]="CO","Conciliacion Cartera","")))))))))))))) | X193: =_xlfn.XLOOKUP(Cartera[[#This Row],[Nombre tercero]],Vendedor[Nombre],Vendedor[Vendedor],"",0,-1) -> JORGE PARDO
A194: ALBA MARIA GONZALEZ IBAÑEZ | B194: 151 | C194: 23759 | D194: 11 | E194: 46022.304 | F194: 46023.283 | G194: 13 | H194: 497700 | I194: 497700 | J194: 0 | K194: 0 | L194: 497700 | M194: 0 | N194: 0 | O194: 0 | P194: =SUM(Cartera[[#This Row],[1_a_8]:[>30]]) -> 497700 | Q194: =+Cartera[[#This Row],[9_a_15]]+Cartera[[#This Row],[16_a_22]]+Cartera[[#This Row],[23_a_30]] -> 497700 | R194: =IF(Cartera[[#This Row],[Dias]]>8,Cartera[[#This Row],[Total vencido]],0) -> 497700 | S194: =IF(Cartera[[#This Row],[Mas de 9]]>0,Cartera[[#This Row],[Dias]],0) -> 13 | T194: =IF(Cartera[[#This Row],[Dias]]>99,Cartera[[#This Row],[Total vencido]],0) -> 0 | U194: =IF(Cartera[[#This Row],[Mas de 100]]>0,Cartera[[#This Row],[Dias]],0) -> 0 | V194: =Cartera[[#This Row],[Vencimiento]]-Cartera[[#This Row],[Emision]] -> 0.97866898 | W194: =+IF(Cartera[[#This Row],[Tipo]]=151,"Lom",IF(Cartera[[#This Row],[Tipo]]=153,"Lom",IF(Cartera[[#This Row],[Tipo]]=155,"Lom",IF(Cartera[[#This Row],[Tipo]]=200,"Lom",IF(Cartera[[#This Row],[Tipo]]=224,"Lom",IF(Cartera[[#This Row],[Tipo]]=251,"Lom",IF(Cartera[[#This Row],[Tipo]]=651,"Magra",IF(Cartera[[#This Row],[Tipo]]=655,"Magra",IF(Cartera[[#This Row],[Tipo]]=601,"Magra",IF(Cartera[[#This Row],[Tipo]]=751,"Galan",IF(Cartera[[#This Row],[Tipo]]=757,"Galan",IF(Cartera[[#This Row],[Tipo]]=701,"Galan",IF(Cartera[[#This Row],[Tipo]]=755,"Galan",IF(Cartera[[#This Row],[Tipo]]="CO","Conciliacion Cartera","")))))))))))))) | X194: =_xlfn.XLOOKUP(Cartera[[#This Row],[Nombre tercero]],Vendedor[Nombre],Vendedor[Vendedor],"",0,-1) -> ANGELA SILVESTRE
A195: ALEJANDRO DURAN | B195: 751 | C195: 16999 | D195: 7 | E195: 45957.477 | F195: 45958.477 | G195: 78 | H195: 1484405 | I195: 1484405 | J195: 0 | K195: 0 | L195: 0 | M195: 0 | N195: 0 | O195: 1484405 | P195: =SUM(Cartera[[#This Row],[1_a_8]:[>30]]) -> 1484405 | Q195: =+Cartera[[#This Row],[9_a_15]]+Cartera[[#This Row],[16_a_22]]+Cartera[[#This Row],[23_a_30]] -> 0 | R195: =IF(Cartera[[#This Row],[Dias]]>8,Cartera[[#This Row],[Total vencido]],0) -> 1484405 | S195: =IF(Cartera[[#This Row],[Mas de 9]]>0,Cartera[[#This Row],[Dias]],0) -> 78 | T195: =IF(Cartera[[#This Row],[Dias]]>99,Cartera[[#This Row],[Total vencido]],0) -> 0 | U195: =IF(Cartera[[#This Row],[Mas de 100]]>0,Cartera[[#This Row],[Dias]],0) -> 0 | V195: =Cartera[[#This Row],[Vencimiento]]-Cartera[[#This Row],[Emision]] -> 0.99988426 | W195: =+IF(Cartera[[#This Row],[Tipo]]=151,"Lom",IF(Cartera[[#This Row],[Tipo]]=153,"Lom",IF(Cartera[[#This Row],[Tipo]]=155,"Lom",IF(Cartera[[#This Row],[Tipo]]=200,"Lom",IF(Cartera[[#This Row],[Tipo]]=224,"Lom",IF(Cartera[[#This Row],[Tipo]]=251,"Lom",IF(Cartera[[#This Row],[Tipo]]=651,"Magra",IF(Cartera[[#This Row],[Tipo]]=655,"Magra",IF(Cartera[[#This Row],[Tipo]]=601,"Magra",IF(Cartera[[#This Row],[Tipo]]=751,"Galan",IF(Cartera[[#This Row],[Tipo]]=757,"Galan",IF(Cartera[[#This Row],[Tipo]]=701,"Galan",IF(Cartera[[#This Row],[Tipo]]=755,"Galan",IF(Cartera[[#This Row],[Tipo]]="CO","Conciliacion Cartera","")))))))))))))) | X195: =_xlfn.XLOOKUP(Cartera[[#This Row],[Nombre tercero]],Vendedor[Nombre],Vendedor[Vendedor],"",0,-1) -> ANGELA SILVESTRE
