Workbook

Sheet LISTADO DE CLIENTES
A1: Nit | B1: Cliente | C1: Nombre comercial | D1: Correo cliente | E1: Vendedor | F1: Correo vendedor | G1: Canal | H1: Cupo | I1: Columna1
A2: 900993503 | B2: A MANO SAS | D2: cg629271@gmail.com | E2: JORGE PARDO | F2: j.gutierrez@grupolom.com | G2: HORECA | H2: =_xlfn.XLOOKUP(Tabla3[[#This Row],[Nit]],Hoja2!A2:A1425,Hoja2!C2:C1425) -> 3000000 | I2: =_xlfn.XLOOKUP(Tabla3[[#This Row],[Cliente]],'[1]Datos Contacto'!$A$2:$A$23,'[1]Datos Contacto'!$E$2:$E$23,0,0,1) -> 0
A3: 900539052 | B3: ABEL Y SOFIA SAS | D3: cg629271@gmail.com | E3: ANGELA SILVESTRE | F3: j.gutierrez@grupolom.com | G3: HORECA | H3: =_xlfn.XLOOKUP(Tabla3[[#This Row],[Nit]],Hoja2!A3:A1426,Hoja2!C3:C1426) -> 150000000 | I3: =_xlfn.XLOOKUP(Tabla3[[#This Row],[Cliente]],'[1]Datos Contacto'!$A$2:$A$23,'[1]Datos Contacto'!$E$2:$E$23,0,0,1) -> asistentetesoreria3@grupogordo.net
A4: 901017839 | B4: ACVL S.A.S | D4: cg629271@gmail.com | E4: JORGE PARDO | F4: j.gutierrez@grupolom.com | G4: Mayoristas | H4: =_xlfn.XLOOKUP(Tabla3[[#This Row],[Nit]],Hoja2!A4:A1427,Hoja2!C4:C1427) -> 1000000 | I4: =_xlfn.XLOOKUP(Tabla3[[#This Row],[Cliente]],'[1]Datos Contacto'!$A$2:$A$23,'[1]Datos Contacto'!$E$2:$E$23,0,0,1) -> 0
A5: 79643388 | B5: ADRIAN ALVAREZ | D5: cg629271@gmail.com | E5: ANGELA SILVESTRE | F5: j.gutierrez@grupolom.com | G5: Mayoristas | H5: =_xlfn.XLOOKUP(Tabla3[[#This Row],[Nit]],Hoja2!A5:A1428,Hoja2!C5:C1428) -> 2000000 | I5: =_xlfn.XLOOKUP(Tabla3[[#This Row],[Cliente]],'[1]Datos Contacto'!$A$2:$A$23,'[1]Datos Contacto'!$E$2:$E$23,0,0,1) -> 0
A6: 52074253 | B6: ADRIANA BERMUDEZ RAMIREZ | D6: cg629271@gmail.com | E6: JORGE PARDO | F6: j.gutierrez@grupolom.com | G6: HORECA | H6: =_xlfn.XLOOKUP(Tabla3[[#This Row],[Nit]],Hoja2!A6:A1429,Hoja2!C6:C1429) -> 4000000 | I6: =_xlfn.XLOOKUP(Tabla3[[#This Row],[Cliente]],'[1]Datos Contacto'!$A$2:$A$23,'[1]Datos Contacto'!$E$2:$E$23,0,0,1) -> 0
A7: 1018454730 | B7: ADRIANA RUBIO MARTINEZ | D7: cg629271@gmail.com | E7: ANGELA SILVESTRE | F7: j.gutierrez@grupolom.com | G7: Mostrador | H7: =_xlfn.XLOOKUP(Tabla3[[#This Row],[Nit]],Hoja2!A7:A1430,Hoja2!C7:C1430) -> 1000000 | I7: =_xlfn.XLOOKUP(Tabla3[[#This Row],[Cliente]],'[1]Datos Contacto'!$A$2:$A$23,'[1]Datos Contacto'!$E$2:$E$23,0,0,1) -> 0
A8: 830059718 | B8: AECSA SAS | D8: cg629271@gmail.com | E8: ANGELA SILVESTRE | F8: j.gutierrez@grupolom.com | G8: HORECA | H8: =_xlfn.XLOOKUP(Tabla3[[#This Row],[Nit]],Hoja2!A8:A1431,Hoja2!C8:C1431) -> 1000000 | I8: =_xlfn.XLOOKUP(Tabla3[[#This Row],[Cliente]],'[1]Datos Contacto'!$A$2:$A$23,'[1]Datos Contacto'!$E$2:$E$23,0,0,1) -> 0
A9: 83056853 | B9: AGROMAS LTDA | D9: cg629271@gmail.com | E9: ANGELA SILVESTRE | F9: j.gutierrez@grupolom.com | G9: Mayoristas | H9: =_xlfn.XLOOKUP(Tabla3[[#This Row],[Nit]],Hoja2!A9:A1432,Hoja2!C9:C1432) -> 2000000 | I9: =_xlfn.XLOOKUP(Tabla3[[#This Row],[Cliente]],'[1]Datos Contacto'!$A$2:$A$23,'[1]Datos Contacto'!$E$2:$E$23,0,0,1) -> 0
A10: 900527483 | B10: AGROPECUARIA EL INGENIO SAS MAGROS CARNES DE CERDO | D10: cg629271@gmail.com | E10: ANGELA SILVESTRE | F10: j.gutierrez@grupolom.com | G10: Mayoristas | H10: =_xlfn.XLOOKUP(Tabla3[[#This Row],[Nit]],Hoja2!A10:A1433,Hoja2!C10:C1433) -> 1000000 | I10: =_xlfn.XLOOKUP(Tabla3[[#This Row],[Cliente]],'[1]Datos Contacto'!$A$2:$A$23,'[1]Datos Contacto'!$E$2:$E$23,0,0,1) -> 0
A11: 890207037 | B11: AGROPUCUARIA ALIAR S.A.S | D11: cg629271@gmail.com | E11: ANGELA SILVESTRE | F11: j.gutierrez@grupolom.com | G11: Industria | H11: =_xlfn.XLOOKUP(Tabla3[[#This Row],[Nit]],Hoja2!A11:A1434,Hoja2!C11:C1434) -> 1000000 | I11: =_xlfn.XLOOKUP(Tabla3[[#This Row],[Cliente]],'[1]Datos Contacto'!$A$2:$A$23,'[1]Datos Contacto'!$E$2:$E$23,0,0,1) -> 0
A12: 901746296 | B12: AGROTODO MENEGUA SAS | D12: cg629271@gmail.com | E12: ANGELA SILVESTRE | F12: j.gutierrez@grupolom.com | G12: Industria | H12: =_xlfn.XLOOKUP(Tabla3[[#This Row],[Nit]],Hoja2!A12:A1435,Hoja2!C12:C1435) -> 1000000 | I12: =_xlfn.XLOOKUP(Tabla3[[#This Row],[Cliente]],'[1]Datos Contacto'!$A$2:$A$23,'[1]Datos Contacto'!$E$2:$E$23,0,0,1) -> 0
A13: 901734623 | B13: AGUA DE AFLUENTES SAS | D13: cg629271@gmail.com | E13: ANGELA SILVESTRE | F13: j.gutierrez@grupolom.com | G13: HORECA | H13: =_xlfn.XLOOKUP(Tabla3[[#This Row],[Nit]],Hoja2!A13:A1436,Hoja2!C13:C1436) -> 1000000 | I13: =_xlfn.XLOOKUP(Tabla3[[#This Row],[Cliente]],'[1]Datos Contacto'!$A$2:$A$23,'[1]Datos Contacto'!$E$2:$E$23,0,0,1) -> 0
... A95: 79382679 | B95: CANDIDO CORTES | D95: cg629271@gmail.com | E95: ANGELA SILVESTRE | F95: j.gutierrez@grupolom.com | G95: Mayoristas | H95: =_xlfn.XLOOKUP(Tabla3[[#This Row],[Nit]],Hoja2!A95:A1518,Hoja2!C95:C1518) -> 1000000 | I95: =_xlfn.XLOOKUP(Tabla3[[#This Row],[Cliente]],'[1]Datos Contacto'!$A$2:$A$23,'[1]Datos Contacto'!$E$2:$E$23,0,0,1) -> 0
A96: 900906554 | B96: CANTINA LA 15 SAS | C96: Cantina la 15 | D96: cg629271@gmail.com | E96: JORGE PARDO | F96: j.gutierrez@grupolom.com | G96: HORECA | H96: =_xlfn.XLOOKUP(Tabla3[[#This Row],[Nit]],Hoja2!A96:A1519,Hoja2!C96:C1519) -> 120000000 | I96: =_xlfn.XLOOKUP(Tabla3[[#This Row],[Cliente]],'[1]Datos Contacto'!$A$2:$A$23,'[1]Datos Contacto'!$E$2:$E$23,0,0,1) -> facturacion@cantinala15.com.co
A97: 901627338 | B97: CAÑAS PERVER SAS | D97: cg629271@gmail.com | E97: ANGELA SILVESTRE | F97: j.gutierrez@grupolom.com | G97: Mayoristas | H97: =_xlfn.XLOOKUP(Tabla3[[#This Row],[Nit]],Hoja2!A97:A1520,Hoja2!C97:C1520) -> 1000000 | I97: =_xlfn.XLOOKUP(Tabla3[[#This Row],[Cliente]],'[1]Datos Contacto'!$A$2:$A$23,'[1]Datos Contacto'!$E$2:$E$23,0,0,1) -> 0
A98: 143 | B98: CARLOS AYALA | D98: cg629271@gmail.com | E98: ANGELA SILVESTRE | F98: j.gutierrez@grupolom.com | G98: Mayoristas | H98: =_xlfn.XLOOKUP(Tabla3[[#This Row],[Nit]],Hoja2!A98:A1521,Hoja2!C98:C1521) -> 1000000 | I98: =_xlfn.XLOOKUP(Tabla3[[#This Row],[Cliente]],'[1]Datos Contacto'!$A$2:$A$23,'[1]Datos Contacto'!$E$2:$E$23,0,0,1) -> 0
A99: 79126370 | B99: CARLOS CUBIDES | D99: cg629271@gmail.com | E99: ANGELA SILVESTRE | F99: j.gutierrez@grupolom.com | G99: HORECA | H99: =_xlfn.XLOOKUP(Tabla3[[#This Row],[Nit]],Hoja2!A99:A1522,Hoja2!C99:C1522) -> 1000000 | I99: =_xlfn.XLOOKUP(Tabla3[[#This Row],[Cliente]],'[1]Datos Contacto'!$A$2:$A$23,'[1]Datos Contacto'!$E$2:$E$23,0,0,1) -> 0
A100: 93392103 | B100: CARLOS FLOREZ | D100: cg629271@gmail.com | E100: ANGELA SILVESTRE | F100: j.gutierrez@grupolom.com | G100: Canal digital | H100: =_xlfn.XLOOKUP(Tabla3[[#This Row],[Nit]],Hoja2!A100:A1523,Hoja2!C100:C1523) -> 1000000 | I100: =_xlfn.XLOOKUP(Tabla3[[#This Row],[Cliente]],'[1]Datos Contacto'!$A$2:$A$23,'[1]Datos Contacto'!$E$2:$E$23,0,0,1) -> 0
A101: 451 | B101: CARLOS GALEANO | D101: cg629271@gmail.com | E101: ANGELA SILVESTRE | F101: j.gutierrez@grupolom.com | G101: Mayoristas | H101: =_xlfn.XLOOKUP(Tabla3[[#This Row],[Nit]],Hoja2!A101:A1524,Hoja2!C101:C1524) -> 1000000 | I101: =_xlfn.XLOOKUP(Tabla3[[#This Row],[Cliente]],'[1]Datos Contacto'!$A$2:$A$23,'[1]Datos Contacto'!$E$2:$E$23,0,0,1) -> 0
A102: 148 | B102: CARLOS LINARES | D102: cg629271@gmail.com | E102: ANGELA SILVESTRE | F102: j.gutierrez@grupolom.com | G102: Mostrador | H102: =_xlfn.XLOOKUP(Tabla3[[#This Row],[Nit]],Hoja2!A102:A1525,Hoja2!C102:C1525) -> 1000000 | I102: =_xlfn.XLOOKUP(Tabla3[[#This Row],[Cliente]],'[1]Datos Contacto'!$A$2:$A$23,'[1]Datos Contacto'!$E$2:$E$23,0,0,1) -> 0
A103: 19226024 | B103: CARLOS NAVARRO | D103: cg629271@gmail.com | E103: ANGELA SILVESTRE | F103: j.gutierrez@grupolom.com | G103: Mayoristas | H103: =_xlfn.XLOOKUP(Tabla3[[#This Row],[Nit]],Hoja2!A103:A1526,Hoja2!C103:C1526) -> 1000000 | I103: =_xlfn.XLOOKUP(Tabla3[[#This Row],[Cliente]],'[1]Datos Contacto'!$A$2:$A$23,'[1]Datos Contacto'!$E$2:$E$23,0,0,1) -> 0
A104: 162 | B104: CARLOS ALBERTO GARAY PLAZAS | D104: cg629271@gmail.com | E104: ANGELA SILVESTRE | F104: j.gutierrez@grupolom.com | G104: Mostrador | H104: =_xlfn.XLOOKUP(Tabla3[[#This Row],[Nit]],Hoja2!A104:A1527,Hoja2!C104:C1527) -> 1000000 | I104: =_xlfn.XLOOKUP(Tabla3[[#This Row],[Cliente]],'[1]Datos Contacto'!$A$2:$A$23,'[1]Datos Contacto'!$E$2:$E$23,0,0,1) -> 0
A105: 80109859 | B105: CARLOS ANDRES BALLESTEROS | D105: cg629271@gmail.com | E105: ANGELA SILVESTRE | F105: j.gutierrez@grupolom.com | G105: Mayoristas | H105: =_xlfn.XLOOKUP(Tabla3[[#This Row],[Nit]],Hoja2!A105:A1528,Hoja2!C105:C1528) -> 1000000 | I105: =_xlfn.XLOOKUP(Tabla3[[#This Row],[Cliente]],'[1]Datos Contacto'!$A$2:$A$23,'[1]Datos Contacto'!$E$2:$E$23,0,0,1) -> 0
A106: 80854452 | B106: CARLOS ANDRES CORTES PACHON | D106: cg629271@gmail.com | E106: ANGELA SILVESTRE | F106: j.gutierrez@grupolom.com | G106: Mayoristas | H106: =_xlfn.XLOOKUP(Tabla3[[#This Row],[Nit]],Hoja2!A106:A1529,Hoja2!C106:C1529) -> 1000000 | I106: =_xlfn.XLOOKUP(Tabla3[[#This Row],[Cliente]],'[1]Datos Contacto'!$A$2:$A$23,'[1]Datos Contacto'!$E$2:$E$23,0,0,1) -> 0
A107: 1042454473 | B107: CARLOS ANDRES HERNANDEZ MARTINEZ | D107: cg629271@gmail.com | E107: ANGELA SILVESTRE | F107: j.gutierrez@grupolom.com | G107: HORECA | H107: =_xlfn.XLOOKUP(Tabla3[[#This Row],[Nit]],Hoja2!A107:A1530,Hoja2!C107:C1530) -> 5000000 | I107: =_xlfn.XLOOKUP(Tabla3[[#This Row],[Cliente]],'[1]Datos Contacto'!$A$2:$A$23,'[1]Datos Contacto'!$E$2:$E$23,0,0,1) -> 0
A108: 1057736403 | B108: CARLOS ANDRES SEPEDA RUBIO | D108: cg629271@gmail.com | E108: ANGELA SILVESTRE | F108: j.gutierrez@grupolom.com | G108: HORECA | H108: =_xlfn.XLOOKUP(Tabla3[[#This Row],[Nit]],Hoja2!A108:A1531,Hoja2!C108:C1531) -> 1000000 | I108: =_xlfn.XLOOKUP(Tabla3[[#This Row],[Cliente]],'[1]Datos Contacto'!$A$2:$A$23,'[1]Datos Contacto'!$E$2:$E$23,0,0,1) -> 0
... A381: 901494655 | B381: INVERSIONES DIMASOL S.A.S | D381: cg629271@gmail.com | E381: ANGELA SILVESTRE | F381: j.gutierrez@grupolom.com | G381: HORECA | H381: =_xlfn.XLOOKUP(Tabla3[[#This Row],[Nit]],Hoja2!A381:A1804,Hoja2!C381:C1804) -> 1000000 | I381: =_xlfn.XLOOKUP(Tabla3[[#This Row],[Cliente]],'[1]Datos Contacto'!$A$2:$A$23,'[1]Datos Contacto'!$E$2:$E$23,0,0,1) -> 0
A382: 830115239 | B382: INVERSIONES EL CARNAL SAS | C382: El Carnal | D382: cg629271@gmail.com | E382: JORGE PARDO | F382: j.gutierrez@grupolom.com | G382: HORECA | H382: =_xlfn.XLOOKUP(Tabla3[[#This Row],[Nit]],Hoja2!A382:A1805,Hoja2!C382:C1805) -> 120000000 | I382: =_xlfn.XLOOKUP(Tabla3[[#This Row],[Cliente]],'[1]Datos Contacto'!$A$2:$A$23,'[1]Datos Contacto'!$E$2:$E$23,0,0,1) -> facturacion2@elcarnal.com.co
A383: 891856457 | B383: INVERSIONES EL DORADO SAS | D383: cg629271@gmail.com | E383: ANGELA SILVESTRE | F383: j.gutierrez@grupolom.com | G383: Industria | H383: =_xlfn.XLOOKUP(Tabla3[[#This Row],[Nit]],Hoja2!A383:A1806,Hoja2!C383:C1806) -> 1000000 | I383: =_xlfn.XLOOKUP(Tabla3[[#This Row],[Cliente]],'[1]Datos Contacto'!$A$2:$A$23,'[1]Datos Contacto'!$E$2:$E$23,0,0,1) -> 0
A384: 900675420 | B384: INVERSIONES GUATOQUE SAS | D384: cg629271@gmail.com | E384: ANGELA SILVESTRE | F384: j.gutierrez@grupolom.com | G384: Mostrador | H384: =_xlfn.XLOOKUP(Tabla3[[#This Row],[Nit]],Hoja2!A384:A1807,Hoja2!C384:C1807) -> 1000000 | I384: =_xlfn.XLOOKUP(Tabla3[[#This Row],[Cliente]],'[1]Datos Contacto'!$A$2:$A$23,'[1]Datos Contacto'!$E$2:$E$23,0,0,1) -> 0
A385: 901354603 | B385: INVERSIONES KHIMAIRA S.A.S | D385: cg629271@gmail.com | E385: ANGELA SILVESTRE | F385: j.gutierrez@grupolom.com | G385: Mayoristas | H385: =_xlfn.XLOOKUP(Tabla3[[#This Row],[Nit]],Hoja2!A385:A1808,Hoja2!C385:C1808) -> 1000000 | I385: =_xlfn.XLOOKUP(Tabla3[[#This Row],[Cliente]],'[1]Datos Contacto'!$A$2:$A$23,'[1]Datos Contacto'!$E$2:$E$23,0,0,1) -> 0
A386: 901494828 | B386: INVERSIONES LA ESPERANZA RBR SAS | D386: cg629271@gmail.com | E386: ANGELA SILVESTRE | F386: j.gutierrez@grupolom.com | G386: HORECA | H386: =_xlfn.XLOOKUP(Tabla3[[#This Row],[Nit]],Hoja2!A386:A1809,Hoja2!C386:C1809) -> 1000000 | I386: =_xlfn.XLOOKUP(Tabla3[[#This Row],[Cliente]],'[1]Datos Contacto'!$A$2:$A$23,'[1]Datos Contacto'!$E$2:$E$23,0,0,1) -> 0
A387: 900793046 | B387: INVERSIONES MARTINEZ FRUTIMAX S.A.S | D387: cg629271@gmail.com | E387: ANGELA SILVESTRE | F387: j.gutierrez@grupolom.com | G387: Industria | H387: =_xlfn.XLOOKUP(Tabla3[[#This Row],[Nit]],Hoja2!A387:A1810,Hoja2!C387:C1810) -> 1000000 | I387: =_xlfn.XLOOKUP(Tabla3[[#This Row],[Cliente]],'[1]Datos Contacto'!$A$2:$A$23,'[1]Datos Contacto'!$E$2:$E$23,0,0,1) -> 0
A388: 901240494 | B388: INVERSIONES MI TIERRITA SAS | D388: cg629271@gmail.com | E388: JORGE PARDO | F388: j.gutierrez@grupolom.com | G388: HORECA | H388: =_xlfn.XLOOKUP(Tabla3[[#This Row],[Nit]],Hoja2!A388:A1811,Hoja2!C388:C1811) -> 20000000 | I388: =_xlfn.XLOOKUP(Tabla3[[#This Row],[Cliente]],'[1]Datos Contacto'!$A$2:$A$23,'[1]Datos Contacto'!$E$2:$E$23,0,0,1) -> 0
A389: 901558589 | B389: INVERSIONES MSA SAS | D389: cg629271@gmail.com | E389: ANGELA SILVESTRE | F389: j.gutierrez@grupolom.com | G389: Mayoristas | H389: =_xlfn.XLOOKUP(Tabla3[[#This Row],[Nit]],Hoja2!A389:A1812,Hoja2!C389:C1812) -> 1000000 | I389: =_xlfn.XLOOKUP(Tabla3[[#This Row],[Cliente]],'[1]Datos Contacto'!$A$2:$A$23,'[1]Datos Contacto'!$E$2:$E$23,0,0,1) -> 0
A390: 901222813 | B390: INVERSIONES NGB & CO SAS | D390: cg629271@gmail.com | E390: ANGELA SILVESTRE | F390: j.gutierrez@grupolom.com | G390: HORECA | H390: =_xlfn.XLOOKUP(Tabla3[[#This Row],[Nit]],Hoja2!A390:A1813,Hoja2!C390:C1813) -> 5000000 | I390: =_xlfn.XLOOKUP(Tabla3[[#This Row],[Cliente]],'[1]Datos Contacto'!$A$2:$A$23,'[1]Datos Contacto'!$E$2:$E$23,0,0,1) -> 0
A391: 901261990 | B391: INVERSIONES ORANGE BLUE SAS | D391: cg629271@gmail.com | E391: ANGELA SILVESTRE | F391: j.gutierrez@grupolom.com | G391: HORECA | H391: =_xlfn.XLOOKUP(Tabla3[[#This Row],[Nit]],Hoja2!A391:A1814,Hoja2!C391:C1814) -> 1000000 | I391: =_xlfn.XLOOKUP(Tabla3[[#This Row],[Cliente]],'[1]Datos Contacto'!$A$2:$A$23,'[1]Datos Contacto'!$E$2:$E$23,0,0,1) -> 0
A392: 901498635 | B392: INVERSIONES PEDERNALES SAS | D392: cg629271@gmail.com | E392: ANGELA SILVESTRE | F392: j.gutierrez@grupolom.com | G392: HORECA | H392: =_xlfn.XLOOKUP(Tabla3[[#This Row],[Nit]],Hoja2!A392:A1815,Hoja2!C392:C1815) -> 1000000 | I392: =_xlfn.XLOOKUP(Tabla3[[#This Row],[Cliente]],'[1]Datos Contacto'!$A$2:$A$23,'[1]Datos Contacto'!$E$2:$E$23,0,0,1) -> 0
A393: 860039586 | B393: IPT INVERSIONES | D393: cg629271@gmail.com | E393: ANGELA SILVESTRE | F393: j.gutierrez@grupolom.com | G393: Mostrador | H393: =_xlfn.XLOOKUP(Tabla3[[#This Row],[Nit]],Hoja2!A393:A1816,Hoja2!C393:C1816) -> 1000000 | I393: =_xlfn.XLOOKUP(Tabla3[[#This Row],[Cliente]],'[1]Datos Contacto'!$A$2:$A$23,'[1]Datos Contacto'!$E$2:$E$23,0,0,1) -> 0
...

Sheet Hoja2
A1: Nit | B1: Nombre | C1: cupo
A2: 901460509 | B2: INGENIERIA SAS | C2: 0
A3: 4047154 | B3: JAIRO NICODEMUS DIAZ ARAGON | C3: 2000000
A4: 901889936 | B4: 4G FOOD SAS | C4: 10000000
A5: 900993503 | B5: A MANO SAS | C5: 3000000
A6: 900539052 | B6: ABEL Y SOFIA SAS | C6: 150000000
A7: 901017839 | B7: ACVL S.A.S | C7: 1000000
A8: 52074253 | B8: ADRIANA BERMUDEZ RAMIREZ | C8: 4000000
A9: 1018454730 | B9: ADRIANA RUBIO MARTINEZ | C9: 1000000
A10: 79643388 | B10: ADRIANO ALVAREZ LOZANO | C10: 2000000
A11: 830059718 | B11: AECSA SAS | C11: 1000000
A12: 83056853 | B12: AGROMAS LTDA | C12: 2000000
A13: 900527483 | B13: AGROPECUARIA EL INGENIO SAS MAGROS CARNES DE CERDO | C13: 1000000
... A1425: 830094751 | B1425: ZX VENTURES COLOMBIA SAS | C1425: 50000000
